[2025-10-13 13:51:47 +0000] [9641] [INFO] Starting gunicorn 21.2.0
[2025-10-13 13:51:47 +0000] [9641] [ERROR] Connection in use: ('0.0.0.0', 8001)
[2025-10-13 13:51:47 +0000] [9641] [ERROR] Retrying in 1 second.
[2025-10-13 13:51:48 +0000] [9641] [ERROR] Connection in use: ('0.0.0.0', 8001)
[2025-10-13 13:51:48 +0000] [9641] [ERROR] Retrying in 1 second.
[2025-10-13 13:51:49 +0000] [9641] [ERROR] Connection in use: ('0.0.0.0', 8001)
[2025-10-13 13:51:49 +0000] [9641] [ERROR] Retrying in 1 second.
[2025-10-13 13:51:50 +0000] [9641] [ERROR] Connection in use: ('0.0.0.0', 8001)
[2025-10-13 13:51:50 +0000] [9641] [ERROR] Retrying in 1 second.
[2025-10-13 13:51:51 +0000] [9641] [ERROR] Connection in use: ('0.0.0.0', 8001)
[2025-10-13 13:51:51 +0000] [9641] [ERROR] Retrying in 1 second.
[2025-10-13 13:51:52 +0000] [9641] [ERROR] Can't connect to ('0.0.0.0', 8001)
[2025-10-13 13:58:09 +0000] [9676] [INFO] Starting gunicorn 21.2.0
[2025-10-13 13:58:09 +0000] [9676] [INFO] Listening at: http://0.0.0.0:8001 (9676)
[2025-10-13 13:58:09 +0000] [9676] [INFO] Using worker: sync
[2025-10-13 13:58:09 +0000] [9677] [INFO] Booting worker with pid: 9677
[2025-10-13 13:58:09 +0000] [9678] [INFO] Booting worker with pid: 9678
[2025-10-13 13:58:09 +0000] [9679] [INFO] Booting worker with pid: 9679
[2025-10-13 13:58:49 +0000] [9679] [ERROR] Error handling request /
Traceback (most recent call last):
  File "/home/ubuntu/Stackly_AI/venv/lib/python3.12/site-packages/django/core/handlers/exception.py", line 55, in inner
    response = get_response(request)
               ^^^^^^^^^^^^^^^^^^^^^
  File "/home/ubuntu/Stackly_AI/venv/lib/python3.12/site-packages/django/utils/deprecation.py", line 119, in __call__
    response = self.process_request(request)
               ^^^^^^^^^^^^^^^^^^^^^^^^^^^^^
  File "/home/ubuntu/Stackly_AI/venv/lib/python3.12/site-packages/django/contrib/messages/middleware.py", line 12, in process_request
    request._messages = default_storage(request)
                        ^^^^^^^^^^^^^^^^^^^^^^^^
  File "/home/ubuntu/Stackly_AI/venv/lib/python3.12/site-packages/django/contrib/messages/storage/__init__.py", line 12, in default_storage
    return import_string(settings.MESSAGE_STORAGE)(request)
           ^^^^^^^^^^^^^^^^^^^^^^^^^^^^^^^^^^^^^^^^^^^^^^^^
  File "/home/ubuntu/Stackly_AI/venv/lib/python3.12/site-packages/django/contrib/messages/storage/fallback.py", line 17, in __init__
    storage_class(*args, **kwargs) for storage_class in self.storage_classes
    ^^^^^^^^^^^^^^^^^^^^^^^^^^^^^^
  File "/home/ubuntu/Stackly_AI/venv/lib/python3.12/site-packages/django/contrib/messages/storage/cookie.py", line 92, in __init__
    self.signer = signing.get_cookie_signer(salt=self.key_salt)
                  ^^^^^^^^^^^^^^^^^^^^^^^^^^^^^^^^^^^^^^^^^^^^^
  File "/home/ubuntu/Stackly_AI/venv/lib/python3.12/site-packages/django/core/signing.py", line 112, in get_cookie_signer
    key=_cookie_signer_key(settings.SECRET_KEY),
                           ^^^^^^^^^^^^^^^^^^^
  File "/home/ubuntu/Stackly_AI/venv/lib/python3.12/site-packages/django/conf/__init__.py", line 90, in __getattr__
    raise ImproperlyConfigured("The SECRET_KEY setting must not be empty.")
django.core.exceptions.ImproperlyConfigured: The SECRET_KEY setting must not be empty.

During handling of the above exception, another exception occurred:

Traceback (most recent call last):
  File "/home/ubuntu/Stackly_AI/venv/lib/python3.12/site-packages/django/core/handlers/exception.py", line 55, in inner
    response = get_response(request)
               ^^^^^^^^^^^^^^^^^^^^^
  File "/home/ubuntu/Stackly_AI/venv/lib/python3.12/site-packages/django/utils/deprecation.py", line 120, in __call__
    response = response or self.get_response(request)
                           ^^^^^^^^^^^^^^^^^^^^^^^^^^
  File "/home/ubuntu/Stackly_AI/venv/lib/python3.12/site-packages/django/core/handlers/exception.py", line 57, in inner
    response = response_for_exception(request, exc)
               ^^^^^^^^^^^^^^^^^^^^^^^^^^^^^^^^^^^^
  File "/home/ubuntu/Stackly_AI/venv/lib/python3.12/site-packages/django/core/handlers/exception.py", line 141, in response_for_exception
    response = handle_uncaught_exception(
               ^^^^^^^^^^^^^^^^^^^^^^^^^^
  File "/home/ubuntu/Stackly_AI/venv/lib/python3.12/site-packages/django/core/handlers/exception.py", line 182, in handle_uncaught_exception
    return debug.technical_500_response(request, *exc_info)
           ^^^^^^^^^^^^^^^^^^^^^^^^^^^^^^^^^^^^^^^^^^^^^^^^
  File "/home/ubuntu/Stackly_AI/venv/lib/python3.12/site-packages/django/views/debug.py", line 69, in technical_500_response
    html = reporter.get_traceback_html()
           ^^^^^^^^^^^^^^^^^^^^^^^^^^^^^
  File "/home/ubuntu/Stackly_AI/venv/lib/python3.12/site-packages/django/views/debug.py", line 428, in get_traceback_html
    c = Context(self.get_traceback_data(), use_l10n=False)
                ^^^^^^^^^^^^^^^^^^^^^^^^^
  File "/home/ubuntu/Stackly_AI/venv/lib/python3.12/site-packages/django/views/debug.py", line 397, in get_traceback_data
    "settings": self.filter.get_safe_settings(),
                ^^^^^^^^^^^^^^^^^^^^^^^^^^^^^^^
  File "/home/ubuntu/Stackly_AI/venv/lib/python3.12/site-packages/django/views/debug.py", line 156, in get_safe_settings
    settings_dict[k] = self.cleanse_setting(k, getattr(settings, k))
                                               ^^^^^^^^^^^^^^^^^^^^
  File "/home/ubuntu/Stackly_AI/venv/lib/python3.12/site-packages/django/conf/__init__.py", line 90, in __getattr__
    raise ImproperlyConfigured("The SECRET_KEY setting must not be empty.")
django.core.exceptions.ImproperlyConfigured: The SECRET_KEY setting must not be empty.

During handling of the above exception, another exception occurred:

Traceback (most recent call last):
  File "/home/ubuntu/Stackly_AI/venv/lib/python3.12/site-packages/django/core/handlers/exception.py", line 55, in inner
    response = get_response(request)
               ^^^^^^^^^^^^^^^^^^^^^
  File "/home/ubuntu/Stackly_AI/venv/lib/python3.12/site-packages/django/utils/deprecation.py", line 120, in __call__
    response = response or self.get_response(request)
                           ^^^^^^^^^^^^^^^^^^^^^^^^^^
  File "/home/ubuntu/Stackly_AI/venv/lib/python3.12/site-packages/django/core/handlers/exception.py", line 57, in inner
    response = response_for_exception(request, exc)
               ^^^^^^^^^^^^^^^^^^^^^^^^^^^^^^^^^^^^
  File "/home/ubuntu/Stackly_AI/venv/lib/python3.12/site-packages/django/core/handlers/exception.py", line 141, in response_for_exception
    response = handle_uncaught_exception(
               ^^^^^^^^^^^^^^^^^^^^^^^^^^
  File "/home/ubuntu/Stackly_AI/venv/lib/python3.12/site-packages/django/core/handlers/exception.py", line 182, in handle_uncaught_exception
    return debug.technical_500_response(request, *exc_info)
           ^^^^^^^^^^^^^^^^^^^^^^^^^^^^^^^^^^^^^^^^^^^^^^^^
  File "/home/ubuntu/Stackly_AI/venv/lib/python3.12/site-packages/django/views/debug.py", line 69, in technical_500_response
    html = reporter.get_traceback_html()
           ^^^^^^^^^^^^^^^^^^^^^^^^^^^^^
  File "/home/ubuntu/Stackly_AI/venv/lib/python3.12/site-packages/django/views/debug.py", line 428, in get_traceback_html
    c = Context(self.get_traceback_data(), use_l10n=False)
                ^^^^^^^^^^^^^^^^^^^^^^^^^
  File "/home/ubuntu/Stackly_AI/venv/lib/python3.12/site-packages/django/views/debug.py", line 397, in get_traceback_data
    "settings": self.filter.get_safe_settings(),
                ^^^^^^^^^^^^^^^^^^^^^^^^^^^^^^^
  File "/home/ubuntu/Stackly_AI/venv/lib/python3.12/site-packages/django/views/debug.py", line 156, in get_safe_settings
    settings_dict[k] = self.cleanse_setting(k, getattr(settings, k))
                                               ^^^^^^^^^^^^^^^^^^^^
  File "/home/ubuntu/Stackly_AI/venv/lib/python3.12/site-packages/django/conf/__init__.py", line 90, in __getattr__
    raise ImproperlyConfigured("The SECRET_KEY setting must not be empty.")
django.core.exceptions.ImproperlyConfigured: The SECRET_KEY setting must not be empty.

During handling of the above exception, another exception occurred:

Traceback (most recent call last):
  File "/home/ubuntu/Stackly_AI/venv/lib/python3.12/site-packages/django/core/handlers/exception.py", line 55, in inner
    response = get_response(request)
               ^^^^^^^^^^^^^^^^^^^^^
  File "/home/ubuntu/Stackly_AI/venv/lib/python3.12/site-packages/django/utils/deprecation.py", line 120, in __call__
    response = response or self.get_response(request)
                           ^^^^^^^^^^^^^^^^^^^^^^^^^^
  File "/home/ubuntu/Stackly_AI/venv/lib/python3.12/site-packages/django/core/handlers/exception.py", line 57, in inner
    response = response_for_exception(request, exc)
               ^^^^^^^^^^^^^^^^^^^^^^^^^^^^^^^^^^^^
  File "/home/ubuntu/Stackly_AI/venv/lib/python3.12/site-packages/django/core/handlers/exception.py", line 141, in response_for_exception
    response = handle_uncaught_exception(
               ^^^^^^^^^^^^^^^^^^^^^^^^^^
  File "/home/ubuntu/Stackly_AI/venv/lib/python3.12/site-packages/django/core/handlers/exception.py", line 182, in handle_uncaught_exception
    return debug.technical_500_response(request, *exc_info)
           ^^^^^^^^^^^^^^^^^^^^^^^^^^^^^^^^^^^^^^^^^^^^^^^^
  File "/home/ubuntu/Stackly_AI/venv/lib/python3.12/site-packages/django/views/debug.py", line 69, in technical_500_response
    html = reporter.get_traceback_html()
           ^^^^^^^^^^^^^^^^^^^^^^^^^^^^^
  File "/home/ubuntu/Stackly_AI/venv/lib/python3.12/site-packages/django/views/debug.py", line 428, in get_traceback_html
    c = Context(self.get_traceback_data(), use_l10n=False)
                ^^^^^^^^^^^^^^^^^^^^^^^^^
  File "/home/ubuntu/Stackly_AI/venv/lib/python3.12/site-packages/django/views/debug.py", line 397, in get_traceback_data
    "settings": self.filter.get_safe_settings(),
                ^^^^^^^^^^^^^^^^^^^^^^^^^^^^^^^
  File "/home/ubuntu/Stackly_AI/venv/lib/python3.12/site-packages/django/views/debug.py", line 156, in get_safe_settings
    settings_dict[k] = self.cleanse_setting(k, getattr(settings, k))
                                               ^^^^^^^^^^^^^^^^^^^^
  File "/home/ubuntu/Stackly_AI/venv/lib/python3.12/site-packages/django/conf/__init__.py", line 90, in __getattr__
    raise ImproperlyConfigured("The SECRET_KEY setting must not be empty.")
django.core.exceptions.ImproperlyConfigured: The SECRET_KEY setting must not be empty.

During handling of the above exception, another exception occurred:

Traceback (most recent call last):
  File "/home/ubuntu/Stackly_AI/venv/lib/python3.12/site-packages/django/core/handlers/exception.py", line 55, in inner
    response = get_response(request)
               ^^^^^^^^^^^^^^^^^^^^^
  File "/home/ubuntu/Stackly_AI/venv/lib/python3.12/site-packages/django/utils/deprecation.py", line 120, in __call__
    response = response or self.get_response(request)
                           ^^^^^^^^^^^^^^^^^^^^^^^^^^
  File "/home/ubuntu/Stackly_AI/venv/lib/python3.12/site-packages/django/core/handlers/exception.py", line 57, in inner
    response = response_for_exception(request, exc)
               ^^^^^^^^^^^^^^^^^^^^^^^^^^^^^^^^^^^^
  File "/home/ubuntu/Stackly_AI/venv/lib/python3.12/site-packages/django/core/handlers/exception.py", line 141, in response_for_exception
    response = handle_uncaught_exception(
               ^^^^^^^^^^^^^^^^^^^^^^^^^^
  File "/home/ubuntu/Stackly_AI/venv/lib/python3.12/site-packages/django/core/handlers/exception.py", line 182, in handle_uncaught_exception
    return debug.technical_500_response(request, *exc_info)
           ^^^^^^^^^^^^^^^^^^^^^^^^^^^^^^^^^^^^^^^^^^^^^^^^
  File "/home/ubuntu/Stackly_AI/venv/lib/python3.12/site-packages/django/views/debug.py", line 69, in technical_500_response
    html = reporter.get_traceback_html()
           ^^^^^^^^^^^^^^^^^^^^^^^^^^^^^
  File "/home/ubuntu/Stackly_AI/venv/lib/python3.12/site-packages/django/views/debug.py", line 428, in get_traceback_html
    c = Context(self.get_traceback_data(), use_l10n=False)
                ^^^^^^^^^^^^^^^^^^^^^^^^^
  File "/home/ubuntu/Stackly_AI/venv/lib/python3.12/site-packages/django/views/debug.py", line 397, in get_traceback_data
    "settings": self.filter.get_safe_settings(),
                ^^^^^^^^^^^^^^^^^^^^^^^^^^^^^^^
  File "/home/ubuntu/Stackly_AI/venv/lib/python3.12/site-packages/django/views/debug.py", line 156, in get_safe_settings
    settings_dict[k] = self.cleanse_setting(k, getattr(settings, k))
                                               ^^^^^^^^^^^^^^^^^^^^
  File "/home/ubuntu/Stackly_AI/venv/lib/python3.12/site-packages/django/conf/__init__.py", line 90, in __getattr__
    raise ImproperlyConfigured("The SECRET_KEY setting must not be empty.")
django.core.exceptions.ImproperlyConfigured: The SECRET_KEY setting must not be empty.

During handling of the above exception, another exception occurred:

Traceback (most recent call last):
  File "/home/ubuntu/Stackly_AI/venv/lib/python3.12/site-packages/django/core/handlers/exception.py", line 55, in inner
    response = get_response(request)
               ^^^^^^^^^^^^^^^^^^^^^
  File "/home/ubuntu/Stackly_AI/venv/lib/python3.12/site-packages/django/utils/deprecation.py", line 120, in __call__
    response = response or self.get_response(request)
                           ^^^^^^^^^^^^^^^^^^^^^^^^^^
  File "/home/ubuntu/Stackly_AI/venv/lib/python3.12/site-packages/django/core/handlers/exception.py", line 57, in inner
    response = response_for_exception(request, exc)
               ^^^^^^^^^^^^^^^^^^^^^^^^^^^^^^^^^^^^
  File "/home/ubuntu/Stackly_AI/venv/lib/python3.12/site-packages/django/core/handlers/exception.py", line 141, in response_for_exception
    response = handle_uncaught_exception(
               ^^^^^^^^^^^^^^^^^^^^^^^^^^
  File "/home/ubuntu/Stackly_AI/venv/lib/python3.12/site-packages/django/core/handlers/exception.py", line 182, in handle_uncaught_exception
    return debug.technical_500_response(request, *exc_info)
           ^^^^^^^^^^^^^^^^^^^^^^^^^^^^^^^^^^^^^^^^^^^^^^^^
  File "/home/ubuntu/Stackly_AI/venv/lib/python3.12/site-packages/django/views/debug.py", line 69, in technical_500_response
    html = reporter.get_traceback_html()
           ^^^^^^^^^^^^^^^^^^^^^^^^^^^^^
  File "/home/ubuntu/Stackly_AI/venv/lib/python3.12/site-packages/django/views/debug.py", line 428, in get_traceback_html
    c = Context(self.get_traceback_data(), use_l10n=False)
                ^^^^^^^^^^^^^^^^^^^^^^^^^
  File "/home/ubuntu/Stackly_AI/venv/lib/python3.12/site-packages/django/views/debug.py", line 397, in get_traceback_data
    "settings": self.filter.get_safe_settings(),
                ^^^^^^^^^^^^^^^^^^^^^^^^^^^^^^^
  File "/home/ubuntu/Stackly_AI/venv/lib/python3.12/site-packages/django/views/debug.py", line 156, in get_safe_settings
    settings_dict[k] = self.cleanse_setting(k, getattr(settings, k))
                                               ^^^^^^^^^^^^^^^^^^^^
  File "/home/ubuntu/Stackly_AI/venv/lib/python3.12/site-packages/django/conf/__init__.py", line 90, in __getattr__
    raise ImproperlyConfigured("The SECRET_KEY setting must not be empty.")
django.core.exceptions.ImproperlyConfigured: The SECRET_KEY setting must not be empty.

During handling of the above exception, another exception occurred:

Traceback (most recent call last):
  File "/home/ubuntu/Stackly_AI/venv/lib/python3.12/site-packages/gunicorn/workers/sync.py", line 135, in handle
    self.handle_request(listener, req, client, addr)
  File "/home/ubuntu/Stackly_AI/venv/lib/python3.12/site-packages/gunicorn/workers/sync.py", line 178, in handle_request
    respiter = self.wsgi(environ, resp.start_response)
               ^^^^^^^^^^^^^^^^^^^^^^^^^^^^^^^^^^^^^^^
  File "/home/ubuntu/Stackly_AI/venv/lib/python3.12/site-packages/django/core/handlers/wsgi.py", line 124, in __call__
    response = self.get_response(request)
               ^^^^^^^^^^^^^^^^^^^^^^^^^^
  File "/home/ubuntu/Stackly_AI/venv/lib/python3.12/site-packages/django/core/handlers/base.py", line 140, in get_response
    response = self._middleware_chain(request)
               ^^^^^^^^^^^^^^^^^^^^^^^^^^^^^^^
  File "/home/ubuntu/Stackly_AI/venv/lib/python3.12/site-packages/django/core/handlers/exception.py", line 57, in inner
    response = response_for_exception(request, exc)
               ^^^^^^^^^^^^^^^^^^^^^^^^^^^^^^^^^^^^
  File "/home/ubuntu/Stackly_AI/venv/lib/python3.12/site-packages/django/core/handlers/exception.py", line 141, in response_for_exception
    response = handle_uncaught_exception(
               ^^^^^^^^^^^^^^^^^^^^^^^^^^
  File "/home/ubuntu/Stackly_AI/venv/lib/python3.12/site-packages/django/core/handlers/exception.py", line 182, in handle_uncaught_exception
    return debug.technical_500_response(request, *exc_info)
           ^^^^^^^^^^^^^^^^^^^^^^^^^^^^^^^^^^^^^^^^^^^^^^^^
  File "/home/ubuntu/Stackly_AI/venv/lib/python3.12/site-packages/django/views/debug.py", line 69, in technical_500_response
    html = reporter.get_traceback_html()
           ^^^^^^^^^^^^^^^^^^^^^^^^^^^^^
  File "/home/ubuntu/Stackly_AI/venv/lib/python3.12/site-packages/django/views/debug.py", line 428, in get_traceback_html
    c = Context(self.get_traceback_data(), use_l10n=False)
                ^^^^^^^^^^^^^^^^^^^^^^^^^
  File "/home/ubuntu/Stackly_AI/venv/lib/python3.12/site-packages/django/views/debug.py", line 397, in get_traceback_data
    "settings": self.filter.get_safe_settings(),
                ^^^^^^^^^^^^^^^^^^^^^^^^^^^^^^^
  File "/home/ubuntu/Stackly_AI/venv/lib/python3.12/site-packages/django/views/debug.py", line 156, in get_safe_settings
    settings_dict[k] = self.cleanse_setting(k, getattr(settings, k))
                                               ^^^^^^^^^^^^^^^^^^^^
  File "/home/ubuntu/Stackly_AI/venv/lib/python3.12/site-packages/django/conf/__init__.py", line 90, in __getattr__
    raise ImproperlyConfigured("The SECRET_KEY setting must not be empty.")
django.core.exceptions.ImproperlyConfigured: The SECRET_KEY setting must not be empty.
[2025-10-13 13:58:49 +0000] [9677] [ERROR] Error handling request /favicon.ico
Traceback (most recent call last):
  File "/home/ubuntu/Stackly_AI/venv/lib/python3.12/site-packages/django/core/handlers/exception.py", line 55, in inner
    response = get_response(request)
               ^^^^^^^^^^^^^^^^^^^^^
  File "/home/ubuntu/Stackly_AI/venv/lib/python3.12/site-packages/django/utils/deprecation.py", line 119, in __call__
    response = self.process_request(request)
               ^^^^^^^^^^^^^^^^^^^^^^^^^^^^^
  File "/home/ubuntu/Stackly_AI/venv/lib/python3.12/site-packages/django/contrib/messages/middleware.py", line 12, in process_request
    request._messages = default_storage(request)
                        ^^^^^^^^^^^^^^^^^^^^^^^^
  File "/home/ubuntu/Stackly_AI/venv/lib/python3.12/site-packages/django/contrib/messages/storage/__init__.py", line 12, in default_storage
    return import_string(settings.MESSAGE_STORAGE)(request)
           ^^^^^^^^^^^^^^^^^^^^^^^^^^^^^^^^^^^^^^^^^^^^^^^^
  File "/home/ubuntu/Stackly_AI/venv/lib/python3.12/site-packages/django/contrib/messages/storage/fallback.py", line 17, in __init__
    storage_class(*args, **kwargs) for storage_class in self.storage_classes
    ^^^^^^^^^^^^^^^^^^^^^^^^^^^^^^
  File "/home/ubuntu/Stackly_AI/venv/lib/python3.12/site-packages/django/contrib/messages/storage/cookie.py", line 92, in __init__
    self.signer = signing.get_cookie_signer(salt=self.key_salt)
                  ^^^^^^^^^^^^^^^^^^^^^^^^^^^^^^^^^^^^^^^^^^^^^
  File "/home/ubuntu/Stackly_AI/venv/lib/python3.12/site-packages/django/core/signing.py", line 112, in get_cookie_signer
    key=_cookie_signer_key(settings.SECRET_KEY),
                           ^^^^^^^^^^^^^^^^^^^
  File "/home/ubuntu/Stackly_AI/venv/lib/python3.12/site-packages/django/conf/__init__.py", line 90, in __getattr__
    raise ImproperlyConfigured("The SECRET_KEY setting must not be empty.")
django.core.exceptions.ImproperlyConfigured: The SECRET_KEY setting must not be empty.

During handling of the above exception, another exception occurred:

Traceback (most recent call last):
  File "/home/ubuntu/Stackly_AI/venv/lib/python3.12/site-packages/django/core/handlers/exception.py", line 55, in inner
    response = get_response(request)
               ^^^^^^^^^^^^^^^^^^^^^
  File "/home/ubuntu/Stackly_AI/venv/lib/python3.12/site-packages/django/utils/deprecation.py", line 120, in __call__
    response = response or self.get_response(request)
                           ^^^^^^^^^^^^^^^^^^^^^^^^^^
  File "/home/ubuntu/Stackly_AI/venv/lib/python3.12/site-packages/django/core/handlers/exception.py", line 57, in inner
    response = response_for_exception(request, exc)
               ^^^^^^^^^^^^^^^^^^^^^^^^^^^^^^^^^^^^
  File "/home/ubuntu/Stackly_AI/venv/lib/python3.12/site-packages/django/core/handlers/exception.py", line 141, in response_for_exception
    response = handle_uncaught_exception(
               ^^^^^^^^^^^^^^^^^^^^^^^^^^
  File "/home/ubuntu/Stackly_AI/venv/lib/python3.12/site-packages/django/core/handlers/exception.py", line 182, in handle_uncaught_exception
    return debug.technical_500_response(request, *exc_info)
           ^^^^^^^^^^^^^^^^^^^^^^^^^^^^^^^^^^^^^^^^^^^^^^^^
  File "/home/ubuntu/Stackly_AI/venv/lib/python3.12/site-packages/django/views/debug.py", line 69, in technical_500_response
    html = reporter.get_traceback_html()
           ^^^^^^^^^^^^^^^^^^^^^^^^^^^^^
  File "/home/ubuntu/Stackly_AI/venv/lib/python3.12/site-packages/django/views/debug.py", line 428, in get_traceback_html
    c = Context(self.get_traceback_data(), use_l10n=False)
                ^^^^^^^^^^^^^^^^^^^^^^^^^
  File "/home/ubuntu/Stackly_AI/venv/lib/python3.12/site-packages/django/views/debug.py", line 397, in get_traceback_data
    "settings": self.filter.get_safe_settings(),
                ^^^^^^^^^^^^^^^^^^^^^^^^^^^^^^^
  File "/home/ubuntu/Stackly_AI/venv/lib/python3.12/site-packages/django/views/debug.py", line 156, in get_safe_settings
    settings_dict[k] = self.cleanse_setting(k, getattr(settings, k))
                                               ^^^^^^^^^^^^^^^^^^^^
  File "/home/ubuntu/Stackly_AI/venv/lib/python3.12/site-packages/django/conf/__init__.py", line 90, in __getattr__
    raise ImproperlyConfigured("The SECRET_KEY setting must not be empty.")
django.core.exceptions.ImproperlyConfigured: The SECRET_KEY setting must not be empty.

During handling of the above exception, another exception occurred:

Traceback (most recent call last):
  File "/home/ubuntu/Stackly_AI/venv/lib/python3.12/site-packages/django/core/handlers/exception.py", line 55, in inner
    response = get_response(request)
               ^^^^^^^^^^^^^^^^^^^^^
  File "/home/ubuntu/Stackly_AI/venv/lib/python3.12/site-packages/django/utils/deprecation.py", line 120, in __call__
    response = response or self.get_response(request)
                           ^^^^^^^^^^^^^^^^^^^^^^^^^^
  File "/home/ubuntu/Stackly_AI/venv/lib/python3.12/site-packages/django/core/handlers/exception.py", line 57, in inner
    response = response_for_exception(request, exc)
               ^^^^^^^^^^^^^^^^^^^^^^^^^^^^^^^^^^^^
  File "/home/ubuntu/Stackly_AI/venv/lib/python3.12/site-packages/django/core/handlers/exception.py", line 141, in response_for_exception
    response = handle_uncaught_exception(
               ^^^^^^^^^^^^^^^^^^^^^^^^^^
  File "/home/ubuntu/Stackly_AI/venv/lib/python3.12/site-packages/django/core/handlers/exception.py", line 182, in handle_uncaught_exception
    return debug.technical_500_response(request, *exc_info)
           ^^^^^^^^^^^^^^^^^^^^^^^^^^^^^^^^^^^^^^^^^^^^^^^^
  File "/home/ubuntu/Stackly_AI/venv/lib/python3.12/site-packages/django/views/debug.py", line 69, in technical_500_response
    html = reporter.get_traceback_html()
           ^^^^^^^^^^^^^^^^^^^^^^^^^^^^^
  File "/home/ubuntu/Stackly_AI/venv/lib/python3.12/site-packages/django/views/debug.py", line 428, in get_traceback_html
    c = Context(self.get_traceback_data(), use_l10n=False)
                ^^^^^^^^^^^^^^^^^^^^^^^^^
  File "/home/ubuntu/Stackly_AI/venv/lib/python3.12/site-packages/django/views/debug.py", line 397, in get_traceback_data
    "settings": self.filter.get_safe_settings(),
                ^^^^^^^^^^^^^^^^^^^^^^^^^^^^^^^
  File "/home/ubuntu/Stackly_AI/venv/lib/python3.12/site-packages/django/views/debug.py", line 156, in get_safe_settings
    settings_dict[k] = self.cleanse_setting(k, getattr(settings, k))
                                               ^^^^^^^^^^^^^^^^^^^^
  File "/home/ubuntu/Stackly_AI/venv/lib/python3.12/site-packages/django/conf/__init__.py", line 90, in __getattr__
    raise ImproperlyConfigured("The SECRET_KEY setting must not be empty.")
django.core.exceptions.ImproperlyConfigured: The SECRET_KEY setting must not be empty.

During handling of the above exception, another exception occurred:

Traceback (most recent call last):
  File "/home/ubuntu/Stackly_AI/venv/lib/python3.12/site-packages/django/core/handlers/exception.py", line 55, in inner
    response = get_response(request)
               ^^^^^^^^^^^^^^^^^^^^^
  File "/home/ubuntu/Stackly_AI/venv/lib/python3.12/site-packages/django/utils/deprecation.py", line 120, in __call__
    response = response or self.get_response(request)
                           ^^^^^^^^^^^^^^^^^^^^^^^^^^
  File "/home/ubuntu/Stackly_AI/venv/lib/python3.12/site-packages/django/core/handlers/exception.py", line 57, in inner
    response = response_for_exception(request, exc)
               ^^^^^^^^^^^^^^^^^^^^^^^^^^^^^^^^^^^^
  File "/home/ubuntu/Stackly_AI/venv/lib/python3.12/site-packages/django/core/handlers/exception.py", line 141, in response_for_exception
    response = handle_uncaught_exception(
               ^^^^^^^^^^^^^^^^^^^^^^^^^^
  File "/home/ubuntu/Stackly_AI/venv/lib/python3.12/site-packages/django/core/handlers/exception.py", line 182, in handle_uncaught_exception
    return debug.technical_500_response(request, *exc_info)
           ^^^^^^^^^^^^^^^^^^^^^^^^^^^^^^^^^^^^^^^^^^^^^^^^
  File "/home/ubuntu/Stackly_AI/venv/lib/python3.12/site-packages/django/views/debug.py", line 69, in technical_500_response
    html = reporter.get_traceback_html()
           ^^^^^^^^^^^^^^^^^^^^^^^^^^^^^
  File "/home/ubuntu/Stackly_AI/venv/lib/python3.12/site-packages/django/views/debug.py", line 428, in get_traceback_html
    c = Context(self.get_traceback_data(), use_l10n=False)
                ^^^^^^^^^^^^^^^^^^^^^^^^^
  File "/home/ubuntu/Stackly_AI/venv/lib/python3.12/site-packages/django/views/debug.py", line 397, in get_traceback_data
    "settings": self.filter.get_safe_settings(),
                ^^^^^^^^^^^^^^^^^^^^^^^^^^^^^^^
  File "/home/ubuntu/Stackly_AI/venv/lib/python3.12/site-packages/django/views/debug.py", line 156, in get_safe_settings
    settings_dict[k] = self.cleanse_setting(k, getattr(settings, k))
                                               ^^^^^^^^^^^^^^^^^^^^
  File "/home/ubuntu/Stackly_AI/venv/lib/python3.12/site-packages/django/conf/__init__.py", line 90, in __getattr__
    raise ImproperlyConfigured("The SECRET_KEY setting must not be empty.")
django.core.exceptions.ImproperlyConfigured: The SECRET_KEY setting must not be empty.

During handling of the above exception, another exception occurred:

Traceback (most recent call last):
  File "/home/ubuntu/Stackly_AI/venv/lib/python3.12/site-packages/django/core/handlers/exception.py", line 55, in inner
    response = get_response(request)
               ^^^^^^^^^^^^^^^^^^^^^
  File "/home/ubuntu/Stackly_AI/venv/lib/python3.12/site-packages/django/utils/deprecation.py", line 120, in __call__
    response = response or self.get_response(request)
                           ^^^^^^^^^^^^^^^^^^^^^^^^^^
  File "/home/ubuntu/Stackly_AI/venv/lib/python3.12/site-packages/django/core/handlers/exception.py", line 57, in inner
    response = response_for_exception(request, exc)
               ^^^^^^^^^^^^^^^^^^^^^^^^^^^^^^^^^^^^
  File "/home/ubuntu/Stackly_AI/venv/lib/python3.12/site-packages/django/core/handlers/exception.py", line 141, in response_for_exception
    response = handle_uncaught_exception(
               ^^^^^^^^^^^^^^^^^^^^^^^^^^
  File "/home/ubuntu/Stackly_AI/venv/lib/python3.12/site-packages/django/core/handlers/exception.py", line 182, in handle_uncaught_exception
    return debug.technical_500_response(request, *exc_info)
           ^^^^^^^^^^^^^^^^^^^^^^^^^^^^^^^^^^^^^^^^^^^^^^^^
  File "/home/ubuntu/Stackly_AI/venv/lib/python3.12/site-packages/django/views/debug.py", line 69, in technical_500_response
    html = reporter.get_traceback_html()
           ^^^^^^^^^^^^^^^^^^^^^^^^^^^^^
  File "/home/ubuntu/Stackly_AI/venv/lib/python3.12/site-packages/django/views/debug.py", line 428, in get_traceback_html
    c = Context(self.get_traceback_data(), use_l10n=False)
                ^^^^^^^^^^^^^^^^^^^^^^^^^
  File "/home/ubuntu/Stackly_AI/venv/lib/python3.12/site-packages/django/views/debug.py", line 397, in get_traceback_data
    "settings": self.filter.get_safe_settings(),
                ^^^^^^^^^^^^^^^^^^^^^^^^^^^^^^^
  File "/home/ubuntu/Stackly_AI/venv/lib/python3.12/site-packages/django/views/debug.py", line 156, in get_safe_settings
    settings_dict[k] = self.cleanse_setting(k, getattr(settings, k))
                                               ^^^^^^^^^^^^^^^^^^^^
  File "/home/ubuntu/Stackly_AI/venv/lib/python3.12/site-packages/django/conf/__init__.py", line 90, in __getattr__
    raise ImproperlyConfigured("The SECRET_KEY setting must not be empty.")
django.core.exceptions.ImproperlyConfigured: The SECRET_KEY setting must not be empty.

During handling of the above exception, another exception occurred:

Traceback (most recent call last):
  File "/home/ubuntu/Stackly_AI/venv/lib/python3.12/site-packages/django/core/handlers/exception.py", line 55, in inner
    response = get_response(request)
               ^^^^^^^^^^^^^^^^^^^^^
  File "/home/ubuntu/Stackly_AI/venv/lib/python3.12/site-packages/django/utils/deprecation.py", line 120, in __call__
    response = response or self.get_response(request)
                           ^^^^^^^^^^^^^^^^^^^^^^^^^^
  File "/home/ubuntu/Stackly_AI/venv/lib/python3.12/site-packages/django/core/handlers/exception.py", line 57, in inner
    response = response_for_exception(request, exc)
               ^^^^^^^^^^^^^^^^^^^^^^^^^^^^^^^^^^^^
  File "/home/ubuntu/Stackly_AI/venv/lib/python3.12/site-packages/django/core/handlers/exception.py", line 141, in response_for_exception
    response = handle_uncaught_exception(
               ^^^^^^^^^^^^^^^^^^^^^^^^^^
  File "/home/ubuntu/Stackly_AI/venv/lib/python3.12/site-packages/django/core/handlers/exception.py", line 182, in handle_uncaught_exception
    return debug.technical_500_response(request, *exc_info)
           ^^^^^^^^^^^^^^^^^^^^^^^^^^^^^^^^^^^^^^^^^^^^^^^^
  File "/home/ubuntu/Stackly_AI/venv/lib/python3.12/site-packages/django/views/debug.py", line 69, in technical_500_response
    html = reporter.get_traceback_html()
           ^^^^^^^^^^^^^^^^^^^^^^^^^^^^^
  File "/home/ubuntu/Stackly_AI/venv/lib/python3.12/site-packages/django/views/debug.py", line 428, in get_traceback_html
    c = Context(self.get_traceback_data(), use_l10n=False)
                ^^^^^^^^^^^^^^^^^^^^^^^^^
  File "/home/ubuntu/Stackly_AI/venv/lib/python3.12/site-packages/django/views/debug.py", line 397, in get_traceback_data
    "settings": self.filter.get_safe_settings(),
                ^^^^^^^^^^^^^^^^^^^^^^^^^^^^^^^
  File "/home/ubuntu/Stackly_AI/venv/lib/python3.12/site-packages/django/views/debug.py", line 156, in get_safe_settings
    settings_dict[k] = self.cleanse_setting(k, getattr(settings, k))
                                               ^^^^^^^^^^^^^^^^^^^^
  File "/home/ubuntu/Stackly_AI/venv/lib/python3.12/site-packages/django/conf/__init__.py", line 90, in __getattr__
    raise ImproperlyConfigured("The SECRET_KEY setting must not be empty.")
django.core.exceptions.ImproperlyConfigured: The SECRET_KEY setting must not be empty.

During handling of the above exception, another exception occurred:

Traceback (most recent call last):
  File "/home/ubuntu/Stackly_AI/venv/lib/python3.12/site-packages/gunicorn/workers/sync.py", line 135, in handle
    self.handle_request(listener, req, client, addr)
  File "/home/ubuntu/Stackly_AI/venv/lib/python3.12/site-packages/gunicorn/workers/sync.py", line 178, in handle_request
    respiter = self.wsgi(environ, resp.start_response)
               ^^^^^^^^^^^^^^^^^^^^^^^^^^^^^^^^^^^^^^^
  File "/home/ubuntu/Stackly_AI/venv/lib/python3.12/site-packages/django/core/handlers/wsgi.py", line 124, in __call__
    response = self.get_response(request)
               ^^^^^^^^^^^^^^^^^^^^^^^^^^
  File "/home/ubuntu/Stackly_AI/venv/lib/python3.12/site-packages/django/core/handlers/base.py", line 140, in get_response
    response = self._middleware_chain(request)
               ^^^^^^^^^^^^^^^^^^^^^^^^^^^^^^^
  File "/home/ubuntu/Stackly_AI/venv/lib/python3.12/site-packages/django/core/handlers/exception.py", line 57, in inner
    response = response_for_exception(request, exc)
               ^^^^^^^^^^^^^^^^^^^^^^^^^^^^^^^^^^^^
  File "/home/ubuntu/Stackly_AI/venv/lib/python3.12/site-packages/django/core/handlers/exception.py", line 141, in response_for_exception
    response = handle_uncaught_exception(
               ^^^^^^^^^^^^^^^^^^^^^^^^^^
  File "/home/ubuntu/Stackly_AI/venv/lib/python3.12/site-packages/django/core/handlers/exception.py", line 182, in handle_uncaught_exception
    return debug.technical_500_response(request, *exc_info)
           ^^^^^^^^^^^^^^^^^^^^^^^^^^^^^^^^^^^^^^^^^^^^^^^^
  File "/home/ubuntu/Stackly_AI/venv/lib/python3.12/site-packages/django/views/debug.py", line 69, in technical_500_response
    html = reporter.get_traceback_html()
           ^^^^^^^^^^^^^^^^^^^^^^^^^^^^^
  File "/home/ubuntu/Stackly_AI/venv/lib/python3.12/site-packages/django/views/debug.py", line 428, in get_traceback_html
    c = Context(self.get_traceback_data(), use_l10n=False)
                ^^^^^^^^^^^^^^^^^^^^^^^^^
  File "/home/ubuntu/Stackly_AI/venv/lib/python3.12/site-packages/django/views/debug.py", line 397, in get_traceback_data
    "settings": self.filter.get_safe_settings(),
                ^^^^^^^^^^^^^^^^^^^^^^^^^^^^^^^
  File "/home/ubuntu/Stackly_AI/venv/lib/python3.12/site-packages/django/views/debug.py", line 156, in get_safe_settings
    settings_dict[k] = self.cleanse_setting(k, getattr(settings, k))
                                               ^^^^^^^^^^^^^^^^^^^^
  File "/home/ubuntu/Stackly_AI/venv/lib/python3.12/site-packages/django/conf/__init__.py", line 90, in __getattr__
    raise ImproperlyConfigured("The SECRET_KEY setting must not be empty.")
django.core.exceptions.ImproperlyConfigured: The SECRET_KEY setting must not be empty.
[2025-10-13 14:03:23 +0000] [9677] [ERROR] Error handling request /
Traceback (most recent call last):
  File "/home/ubuntu/Stackly_AI/venv/lib/python3.12/site-packages/django/core/handlers/exception.py", line 55, in inner
    response = get_response(request)
               ^^^^^^^^^^^^^^^^^^^^^
  File "/home/ubuntu/Stackly_AI/venv/lib/python3.12/site-packages/django/utils/deprecation.py", line 119, in __call__
    response = self.process_request(request)
               ^^^^^^^^^^^^^^^^^^^^^^^^^^^^^
  File "/home/ubuntu/Stackly_AI/venv/lib/python3.12/site-packages/django/contrib/messages/middleware.py", line 12, in process_request
    request._messages = default_storage(request)
                        ^^^^^^^^^^^^^^^^^^^^^^^^
  File "/home/ubuntu/Stackly_AI/venv/lib/python3.12/site-packages/django/contrib/messages/storage/__init__.py", line 12, in default_storage
    return import_string(settings.MESSAGE_STORAGE)(request)
           ^^^^^^^^^^^^^^^^^^^^^^^^^^^^^^^^^^^^^^^^^^^^^^^^
  File "/home/ubuntu/Stackly_AI/venv/lib/python3.12/site-packages/django/contrib/messages/storage/fallback.py", line 17, in __init__
    storage_class(*args, **kwargs) for storage_class in self.storage_classes
    ^^^^^^^^^^^^^^^^^^^^^^^^^^^^^^
  File "/home/ubuntu/Stackly_AI/venv/lib/python3.12/site-packages/django/contrib/messages/storage/cookie.py", line 92, in __init__
    self.signer = signing.get_cookie_signer(salt=self.key_salt)
                  ^^^^^^^^^^^^^^^^^^^^^^^^^^^^^^^^^^^^^^^^^^^^^
  File "/home/ubuntu/Stackly_AI/venv/lib/python3.12/site-packages/django/core/signing.py", line 112, in get_cookie_signer
    key=_cookie_signer_key(settings.SECRET_KEY),
                           ^^^^^^^^^^^^^^^^^^^
  File "/home/ubuntu/Stackly_AI/venv/lib/python3.12/site-packages/django/conf/__init__.py", line 90, in __getattr__
    raise ImproperlyConfigured("The SECRET_KEY setting must not be empty.")
django.core.exceptions.ImproperlyConfigured: The SECRET_KEY setting must not be empty.

During handling of the above exception, another exception occurred:

Traceback (most recent call last):
  File "/home/ubuntu/Stackly_AI/venv/lib/python3.12/site-packages/django/core/handlers/exception.py", line 55, in inner
    response = get_response(request)
               ^^^^^^^^^^^^^^^^^^^^^
  File "/home/ubuntu/Stackly_AI/venv/lib/python3.12/site-packages/django/utils/deprecation.py", line 120, in __call__
    response = response or self.get_response(request)
                           ^^^^^^^^^^^^^^^^^^^^^^^^^^
  File "/home/ubuntu/Stackly_AI/venv/lib/python3.12/site-packages/django/core/handlers/exception.py", line 57, in inner
    response = response_for_exception(request, exc)
               ^^^^^^^^^^^^^^^^^^^^^^^^^^^^^^^^^^^^
  File "/home/ubuntu/Stackly_AI/venv/lib/python3.12/site-packages/django/core/handlers/exception.py", line 141, in response_for_exception
    response = handle_uncaught_exception(
               ^^^^^^^^^^^^^^^^^^^^^^^^^^
  File "/home/ubuntu/Stackly_AI/venv/lib/python3.12/site-packages/django/core/handlers/exception.py", line 182, in handle_uncaught_exception
    return debug.technical_500_response(request, *exc_info)
           ^^^^^^^^^^^^^^^^^^^^^^^^^^^^^^^^^^^^^^^^^^^^^^^^
  File "/home/ubuntu/Stackly_AI/venv/lib/python3.12/site-packages/django/views/debug.py", line 69, in technical_500_response
    html = reporter.get_traceback_html()
           ^^^^^^^^^^^^^^^^^^^^^^^^^^^^^
  File "/home/ubuntu/Stackly_AI/venv/lib/python3.12/site-packages/django/views/debug.py", line 428, in get_traceback_html
    c = Context(self.get_traceback_data(), use_l10n=False)
                ^^^^^^^^^^^^^^^^^^^^^^^^^
  File "/home/ubuntu/Stackly_AI/venv/lib/python3.12/site-packages/django/views/debug.py", line 397, in get_traceback_data
    "settings": self.filter.get_safe_settings(),
                ^^^^^^^^^^^^^^^^^^^^^^^^^^^^^^^
  File "/home/ubuntu/Stackly_AI/venv/lib/python3.12/site-packages/django/views/debug.py", line 156, in get_safe_settings
    settings_dict[k] = self.cleanse_setting(k, getattr(settings, k))
                                               ^^^^^^^^^^^^^^^^^^^^
  File "/home/ubuntu/Stackly_AI/venv/lib/python3.12/site-packages/django/conf/__init__.py", line 90, in __getattr__
    raise ImproperlyConfigured("The SECRET_KEY setting must not be empty.")
django.core.exceptions.ImproperlyConfigured: The SECRET_KEY setting must not be empty.

During handling of the above exception, another exception occurred:

Traceback (most recent call last):
  File "/home/ubuntu/Stackly_AI/venv/lib/python3.12/site-packages/django/core/handlers/exception.py", line 55, in inner
    response = get_response(request)
               ^^^^^^^^^^^^^^^^^^^^^
  File "/home/ubuntu/Stackly_AI/venv/lib/python3.12/site-packages/django/utils/deprecation.py", line 120, in __call__
    response = response or self.get_response(request)
                           ^^^^^^^^^^^^^^^^^^^^^^^^^^
  File "/home/ubuntu/Stackly_AI/venv/lib/python3.12/site-packages/django/core/handlers/exception.py", line 57, in inner
    response = response_for_exception(request, exc)
               ^^^^^^^^^^^^^^^^^^^^^^^^^^^^^^^^^^^^
  File "/home/ubuntu/Stackly_AI/venv/lib/python3.12/site-packages/django/core/handlers/exception.py", line 141, in response_for_exception
    response = handle_uncaught_exception(
               ^^^^^^^^^^^^^^^^^^^^^^^^^^
  File "/home/ubuntu/Stackly_AI/venv/lib/python3.12/site-packages/django/core/handlers/exception.py", line 182, in handle_uncaught_exception
    return debug.technical_500_response(request, *exc_info)
           ^^^^^^^^^^^^^^^^^^^^^^^^^^^^^^^^^^^^^^^^^^^^^^^^
  File "/home/ubuntu/Stackly_AI/venv/lib/python3.12/site-packages/django/views/debug.py", line 69, in technical_500_response
    html = reporter.get_traceback_html()
           ^^^^^^^^^^^^^^^^^^^^^^^^^^^^^
  File "/home/ubuntu/Stackly_AI/venv/lib/python3.12/site-packages/django/views/debug.py", line 428, in get_traceback_html
    c = Context(self.get_traceback_data(), use_l10n=False)
                ^^^^^^^^^^^^^^^^^^^^^^^^^
  File "/home/ubuntu/Stackly_AI/venv/lib/python3.12/site-packages/django/views/debug.py", line 397, in get_traceback_data
    "settings": self.filter.get_safe_settings(),
                ^^^^^^^^^^^^^^^^^^^^^^^^^^^^^^^
  File "/home/ubuntu/Stackly_AI/venv/lib/python3.12/site-packages/django/views/debug.py", line 156, in get_safe_settings
    settings_dict[k] = self.cleanse_setting(k, getattr(settings, k))
                                               ^^^^^^^^^^^^^^^^^^^^
  File "/home/ubuntu/Stackly_AI/venv/lib/python3.12/site-packages/django/conf/__init__.py", line 90, in __getattr__
    raise ImproperlyConfigured("The SECRET_KEY setting must not be empty.")
django.core.exceptions.ImproperlyConfigured: The SECRET_KEY setting must not be empty.

During handling of the above exception, another exception occurred:

Traceback (most recent call last):
  File "/home/ubuntu/Stackly_AI/venv/lib/python3.12/site-packages/django/core/handlers/exception.py", line 55, in inner
    response = get_response(request)
               ^^^^^^^^^^^^^^^^^^^^^
  File "/home/ubuntu/Stackly_AI/venv/lib/python3.12/site-packages/django/utils/deprecation.py", line 120, in __call__
    response = response or self.get_response(request)
                           ^^^^^^^^^^^^^^^^^^^^^^^^^^
  File "/home/ubuntu/Stackly_AI/venv/lib/python3.12/site-packages/django/core/handlers/exception.py", line 57, in inner
    response = response_for_exception(request, exc)
               ^^^^^^^^^^^^^^^^^^^^^^^^^^^^^^^^^^^^
  File "/home/ubuntu/Stackly_AI/venv/lib/python3.12/site-packages/django/core/handlers/exception.py", line 141, in response_for_exception
    response = handle_uncaught_exception(
               ^^^^^^^^^^^^^^^^^^^^^^^^^^
  File "/home/ubuntu/Stackly_AI/venv/lib/python3.12/site-packages/django/core/handlers/exception.py", line 182, in handle_uncaught_exception
    return debug.technical_500_response(request, *exc_info)
           ^^^^^^^^^^^^^^^^^^^^^^^^^^^^^^^^^^^^^^^^^^^^^^^^
  File "/home/ubuntu/Stackly_AI/venv/lib/python3.12/site-packages/django/views/debug.py", line 69, in technical_500_response
    html = reporter.get_traceback_html()
           ^^^^^^^^^^^^^^^^^^^^^^^^^^^^^
  File "/home/ubuntu/Stackly_AI/venv/lib/python3.12/site-packages/django/views/debug.py", line 428, in get_traceback_html
    c = Context(self.get_traceback_data(), use_l10n=False)
                ^^^^^^^^^^^^^^^^^^^^^^^^^
  File "/home/ubuntu/Stackly_AI/venv/lib/python3.12/site-packages/django/views/debug.py", line 397, in get_traceback_data
    "settings": self.filter.get_safe_settings(),
                ^^^^^^^^^^^^^^^^^^^^^^^^^^^^^^^
  File "/home/ubuntu/Stackly_AI/venv/lib/python3.12/site-packages/django/views/debug.py", line 156, in get_safe_settings
    settings_dict[k] = self.cleanse_setting(k, getattr(settings, k))
                                               ^^^^^^^^^^^^^^^^^^^^
  File "/home/ubuntu/Stackly_AI/venv/lib/python3.12/site-packages/django/conf/__init__.py", line 90, in __getattr__
    raise ImproperlyConfigured("The SECRET_KEY setting must not be empty.")
django.core.exceptions.ImproperlyConfigured: The SECRET_KEY setting must not be empty.

During handling of the above exception, another exception occurred:

Traceback (most recent call last):
  File "/home/ubuntu/Stackly_AI/venv/lib/python3.12/site-packages/django/core/handlers/exception.py", line 55, in inner
    response = get_response(request)
               ^^^^^^^^^^^^^^^^^^^^^
  File "/home/ubuntu/Stackly_AI/venv/lib/python3.12/site-packages/django/utils/deprecation.py", line 120, in __call__
    response = response or self.get_response(request)
                           ^^^^^^^^^^^^^^^^^^^^^^^^^^
  File "/home/ubuntu/Stackly_AI/venv/lib/python3.12/site-packages/django/core/handlers/exception.py", line 57, in inner
    response = response_for_exception(request, exc)
               ^^^^^^^^^^^^^^^^^^^^^^^^^^^^^^^^^^^^
  File "/home/ubuntu/Stackly_AI/venv/lib/python3.12/site-packages/django/core/handlers/exception.py", line 141, in response_for_exception
    response = handle_uncaught_exception(
               ^^^^^^^^^^^^^^^^^^^^^^^^^^
  File "/home/ubuntu/Stackly_AI/venv/lib/python3.12/site-packages/django/core/handlers/exception.py", line 182, in handle_uncaught_exception
    return debug.technical_500_response(request, *exc_info)
           ^^^^^^^^^^^^^^^^^^^^^^^^^^^^^^^^^^^^^^^^^^^^^^^^
  File "/home/ubuntu/Stackly_AI/venv/lib/python3.12/site-packages/django/views/debug.py", line 69, in technical_500_response
    html = reporter.get_traceback_html()
           ^^^^^^^^^^^^^^^^^^^^^^^^^^^^^
  File "/home/ubuntu/Stackly_AI/venv/lib/python3.12/site-packages/django/views/debug.py", line 428, in get_traceback_html
    c = Context(self.get_traceback_data(), use_l10n=False)
                ^^^^^^^^^^^^^^^^^^^^^^^^^
  File "/home/ubuntu/Stackly_AI/venv/lib/python3.12/site-packages/django/views/debug.py", line 397, in get_traceback_data
    "settings": self.filter.get_safe_settings(),
                ^^^^^^^^^^^^^^^^^^^^^^^^^^^^^^^
  File "/home/ubuntu/Stackly_AI/venv/lib/python3.12/site-packages/django/views/debug.py", line 156, in get_safe_settings
    settings_dict[k] = self.cleanse_setting(k, getattr(settings, k))
                                               ^^^^^^^^^^^^^^^^^^^^
  File "/home/ubuntu/Stackly_AI/venv/lib/python3.12/site-packages/django/conf/__init__.py", line 90, in __getattr__
    raise ImproperlyConfigured("The SECRET_KEY setting must not be empty.")
django.core.exceptions.ImproperlyConfigured: The SECRET_KEY setting must not be empty.

During handling of the above exception, another exception occurred:

Traceback (most recent call last):
  File "/home/ubuntu/Stackly_AI/venv/lib/python3.12/site-packages/django/core/handlers/exception.py", line 55, in inner
    response = get_response(request)
               ^^^^^^^^^^^^^^^^^^^^^
  File "/home/ubuntu/Stackly_AI/venv/lib/python3.12/site-packages/django/utils/deprecation.py", line 120, in __call__
    response = response or self.get_response(request)
                           ^^^^^^^^^^^^^^^^^^^^^^^^^^
  File "/home/ubuntu/Stackly_AI/venv/lib/python3.12/site-packages/django/core/handlers/exception.py", line 57, in inner
    response = response_for_exception(request, exc)
               ^^^^^^^^^^^^^^^^^^^^^^^^^^^^^^^^^^^^
  File "/home/ubuntu/Stackly_AI/venv/lib/python3.12/site-packages/django/core/handlers/exception.py", line 141, in response_for_exception
    response = handle_uncaught_exception(
               ^^^^^^^^^^^^^^^^^^^^^^^^^^
  File "/home/ubuntu/Stackly_AI/venv/lib/python3.12/site-packages/django/core/handlers/exception.py", line 182, in handle_uncaught_exception
    return debug.technical_500_response(request, *exc_info)
           ^^^^^^^^^^^^^^^^^^^^^^^^^^^^^^^^^^^^^^^^^^^^^^^^
  File "/home/ubuntu/Stackly_AI/venv/lib/python3.12/site-packages/django/views/debug.py", line 69, in technical_500_response
    html = reporter.get_traceback_html()
           ^^^^^^^^^^^^^^^^^^^^^^^^^^^^^
  File "/home/ubuntu/Stackly_AI/venv/lib/python3.12/site-packages/django/views/debug.py", line 428, in get_traceback_html
    c = Context(self.get_traceback_data(), use_l10n=False)
                ^^^^^^^^^^^^^^^^^^^^^^^^^
  File "/home/ubuntu/Stackly_AI/venv/lib/python3.12/site-packages/django/views/debug.py", line 397, in get_traceback_data
    "settings": self.filter.get_safe_settings(),
                ^^^^^^^^^^^^^^^^^^^^^^^^^^^^^^^
  File "/home/ubuntu/Stackly_AI/venv/lib/python3.12/site-packages/django/views/debug.py", line 156, in get_safe_settings
    settings_dict[k] = self.cleanse_setting(k, getattr(settings, k))
                                               ^^^^^^^^^^^^^^^^^^^^
  File "/home/ubuntu/Stackly_AI/venv/lib/python3.12/site-packages/django/conf/__init__.py", line 90, in __getattr__
    raise ImproperlyConfigured("The SECRET_KEY setting must not be empty.")
django.core.exceptions.ImproperlyConfigured: The SECRET_KEY setting must not be empty.

During handling of the above exception, another exception occurred:

Traceback (most recent call last):
  File "/home/ubuntu/Stackly_AI/venv/lib/python3.12/site-packages/gunicorn/workers/sync.py", line 135, in handle
    self.handle_request(listener, req, client, addr)
  File "/home/ubuntu/Stackly_AI/venv/lib/python3.12/site-packages/gunicorn/workers/sync.py", line 178, in handle_request
    respiter = self.wsgi(environ, resp.start_response)
               ^^^^^^^^^^^^^^^^^^^^^^^^^^^^^^^^^^^^^^^
  File "/home/ubuntu/Stackly_AI/venv/lib/python3.12/site-packages/django/core/handlers/wsgi.py", line 124, in __call__
    response = self.get_response(request)
               ^^^^^^^^^^^^^^^^^^^^^^^^^^
  File "/home/ubuntu/Stackly_AI/venv/lib/python3.12/site-packages/django/core/handlers/base.py", line 140, in get_response
    response = self._middleware_chain(request)
               ^^^^^^^^^^^^^^^^^^^^^^^^^^^^^^^
  File "/home/ubuntu/Stackly_AI/venv/lib/python3.12/site-packages/django/core/handlers/exception.py", line 57, in inner
    response = response_for_exception(request, exc)
               ^^^^^^^^^^^^^^^^^^^^^^^^^^^^^^^^^^^^
  File "/home/ubuntu/Stackly_AI/venv/lib/python3.12/site-packages/django/core/handlers/exception.py", line 141, in response_for_exception
    response = handle_uncaught_exception(
               ^^^^^^^^^^^^^^^^^^^^^^^^^^
  File "/home/ubuntu/Stackly_AI/venv/lib/python3.12/site-packages/django/core/handlers/exception.py", line 182, in handle_uncaught_exception
    return debug.technical_500_response(request, *exc_info)
           ^^^^^^^^^^^^^^^^^^^^^^^^^^^^^^^^^^^^^^^^^^^^^^^^
  File "/home/ubuntu/Stackly_AI/venv/lib/python3.12/site-packages/django/views/debug.py", line 69, in technical_500_response
    html = reporter.get_traceback_html()
           ^^^^^^^^^^^^^^^^^^^^^^^^^^^^^
  File "/home/ubuntu/Stackly_AI/venv/lib/python3.12/site-packages/django/views/debug.py", line 428, in get_traceback_html
    c = Context(self.get_traceback_data(), use_l10n=False)
                ^^^^^^^^^^^^^^^^^^^^^^^^^
  File "/home/ubuntu/Stackly_AI/venv/lib/python3.12/site-packages/django/views/debug.py", line 397, in get_traceback_data
    "settings": self.filter.get_safe_settings(),
                ^^^^^^^^^^^^^^^^^^^^^^^^^^^^^^^
  File "/home/ubuntu/Stackly_AI/venv/lib/python3.12/site-packages/django/views/debug.py", line 156, in get_safe_settings
    settings_dict[k] = self.cleanse_setting(k, getattr(settings, k))
                                               ^^^^^^^^^^^^^^^^^^^^
  File "/home/ubuntu/Stackly_AI/venv/lib/python3.12/site-packages/django/conf/__init__.py", line 90, in __getattr__
    raise ImproperlyConfigured("The SECRET_KEY setting must not be empty.")
django.core.exceptions.ImproperlyConfigured: The SECRET_KEY setting must not be empty.
[2025-10-13 14:03:24 +0000] [9678] [ERROR] Error handling request /favicon.ico
Traceback (most recent call last):
  File "/home/ubuntu/Stackly_AI/venv/lib/python3.12/site-packages/django/core/handlers/exception.py", line 55, in inner
    response = get_response(request)
               ^^^^^^^^^^^^^^^^^^^^^
  File "/home/ubuntu/Stackly_AI/venv/lib/python3.12/site-packages/django/utils/deprecation.py", line 119, in __call__
    response = self.process_request(request)
               ^^^^^^^^^^^^^^^^^^^^^^^^^^^^^
  File "/home/ubuntu/Stackly_AI/venv/lib/python3.12/site-packages/django/contrib/messages/middleware.py", line 12, in process_request
    request._messages = default_storage(request)
                        ^^^^^^^^^^^^^^^^^^^^^^^^
  File "/home/ubuntu/Stackly_AI/venv/lib/python3.12/site-packages/django/contrib/messages/storage/__init__.py", line 12, in default_storage
    return import_string(settings.MESSAGE_STORAGE)(request)
           ^^^^^^^^^^^^^^^^^^^^^^^^^^^^^^^^^^^^^^^^^^^^^^^^
  File "/home/ubuntu/Stackly_AI/venv/lib/python3.12/site-packages/django/contrib/messages/storage/fallback.py", line 17, in __init__
    storage_class(*args, **kwargs) for storage_class in self.storage_classes
    ^^^^^^^^^^^^^^^^^^^^^^^^^^^^^^
  File "/home/ubuntu/Stackly_AI/venv/lib/python3.12/site-packages/django/contrib/messages/storage/cookie.py", line 92, in __init__
    self.signer = signing.get_cookie_signer(salt=self.key_salt)
                  ^^^^^^^^^^^^^^^^^^^^^^^^^^^^^^^^^^^^^^^^^^^^^
  File "/home/ubuntu/Stackly_AI/venv/lib/python3.12/site-packages/django/core/signing.py", line 112, in get_cookie_signer
    key=_cookie_signer_key(settings.SECRET_KEY),
                           ^^^^^^^^^^^^^^^^^^^
  File "/home/ubuntu/Stackly_AI/venv/lib/python3.12/site-packages/django/conf/__init__.py", line 90, in __getattr__
    raise ImproperlyConfigured("The SECRET_KEY setting must not be empty.")
django.core.exceptions.ImproperlyConfigured: The SECRET_KEY setting must not be empty.

During handling of the above exception, another exception occurred:

Traceback (most recent call last):
  File "/home/ubuntu/Stackly_AI/venv/lib/python3.12/site-packages/django/core/handlers/exception.py", line 55, in inner
    response = get_response(request)
               ^^^^^^^^^^^^^^^^^^^^^
  File "/home/ubuntu/Stackly_AI/venv/lib/python3.12/site-packages/django/utils/deprecation.py", line 120, in __call__
    response = response or self.get_response(request)
                           ^^^^^^^^^^^^^^^^^^^^^^^^^^
  File "/home/ubuntu/Stackly_AI/venv/lib/python3.12/site-packages/django/core/handlers/exception.py", line 57, in inner
    response = response_for_exception(request, exc)
               ^^^^^^^^^^^^^^^^^^^^^^^^^^^^^^^^^^^^
  File "/home/ubuntu/Stackly_AI/venv/lib/python3.12/site-packages/django/core/handlers/exception.py", line 141, in response_for_exception
    response = handle_uncaught_exception(
               ^^^^^^^^^^^^^^^^^^^^^^^^^^
  File "/home/ubuntu/Stackly_AI/venv/lib/python3.12/site-packages/django/core/handlers/exception.py", line 182, in handle_uncaught_exception
    return debug.technical_500_response(request, *exc_info)
           ^^^^^^^^^^^^^^^^^^^^^^^^^^^^^^^^^^^^^^^^^^^^^^^^
  File "/home/ubuntu/Stackly_AI/venv/lib/python3.12/site-packages/django/views/debug.py", line 69, in technical_500_response
    html = reporter.get_traceback_html()
           ^^^^^^^^^^^^^^^^^^^^^^^^^^^^^
  File "/home/ubuntu/Stackly_AI/venv/lib/python3.12/site-packages/django/views/debug.py", line 428, in get_traceback_html
    c = Context(self.get_traceback_data(), use_l10n=False)
                ^^^^^^^^^^^^^^^^^^^^^^^^^
  File "/home/ubuntu/Stackly_AI/venv/lib/python3.12/site-packages/django/views/debug.py", line 397, in get_traceback_data
    "settings": self.filter.get_safe_settings(),
                ^^^^^^^^^^^^^^^^^^^^^^^^^^^^^^^
  File "/home/ubuntu/Stackly_AI/venv/lib/python3.12/site-packages/django/views/debug.py", line 156, in get_safe_settings
    settings_dict[k] = self.cleanse_setting(k, getattr(settings, k))
                                               ^^^^^^^^^^^^^^^^^^^^
  File "/home/ubuntu/Stackly_AI/venv/lib/python3.12/site-packages/django/conf/__init__.py", line 90, in __getattr__
    raise ImproperlyConfigured("The SECRET_KEY setting must not be empty.")
django.core.exceptions.ImproperlyConfigured: The SECRET_KEY setting must not be empty.

During handling of the above exception, another exception occurred:

Traceback (most recent call last):
  File "/home/ubuntu/Stackly_AI/venv/lib/python3.12/site-packages/django/core/handlers/exception.py", line 55, in inner
    response = get_response(request)
               ^^^^^^^^^^^^^^^^^^^^^
  File "/home/ubuntu/Stackly_AI/venv/lib/python3.12/site-packages/django/utils/deprecation.py", line 120, in __call__
    response = response or self.get_response(request)
                           ^^^^^^^^^^^^^^^^^^^^^^^^^^
  File "/home/ubuntu/Stackly_AI/venv/lib/python3.12/site-packages/django/core/handlers/exception.py", line 57, in inner
    response = response_for_exception(request, exc)
               ^^^^^^^^^^^^^^^^^^^^^^^^^^^^^^^^^^^^
  File "/home/ubuntu/Stackly_AI/venv/lib/python3.12/site-packages/django/core/handlers/exception.py", line 141, in response_for_exception
    response = handle_uncaught_exception(
               ^^^^^^^^^^^^^^^^^^^^^^^^^^
  File "/home/ubuntu/Stackly_AI/venv/lib/python3.12/site-packages/django/core/handlers/exception.py", line 182, in handle_uncaught_exception
    return debug.technical_500_response(request, *exc_info)
           ^^^^^^^^^^^^^^^^^^^^^^^^^^^^^^^^^^^^^^^^^^^^^^^^
  File "/home/ubuntu/Stackly_AI/venv/lib/python3.12/site-packages/django/views/debug.py", line 69, in technical_500_response
    html = reporter.get_traceback_html()
           ^^^^^^^^^^^^^^^^^^^^^^^^^^^^^
  File "/home/ubuntu/Stackly_AI/venv/lib/python3.12/site-packages/django/views/debug.py", line 428, in get_traceback_html
    c = Context(self.get_traceback_data(), use_l10n=False)
                ^^^^^^^^^^^^^^^^^^^^^^^^^
  File "/home/ubuntu/Stackly_AI/venv/lib/python3.12/site-packages/django/views/debug.py", line 397, in get_traceback_data
    "settings": self.filter.get_safe_settings(),
                ^^^^^^^^^^^^^^^^^^^^^^^^^^^^^^^
  File "/home/ubuntu/Stackly_AI/venv/lib/python3.12/site-packages/django/views/debug.py", line 156, in get_safe_settings
    settings_dict[k] = self.cleanse_setting(k, getattr(settings, k))
                                               ^^^^^^^^^^^^^^^^^^^^
  File "/home/ubuntu/Stackly_AI/venv/lib/python3.12/site-packages/django/conf/__init__.py", line 90, in __getattr__
    raise ImproperlyConfigured("The SECRET_KEY setting must not be empty.")
django.core.exceptions.ImproperlyConfigured: The SECRET_KEY setting must not be empty.

During handling of the above exception, another exception occurred:

Traceback (most recent call last):
  File "/home/ubuntu/Stackly_AI/venv/lib/python3.12/site-packages/django/core/handlers/exception.py", line 55, in inner
    response = get_response(request)
               ^^^^^^^^^^^^^^^^^^^^^
  File "/home/ubuntu/Stackly_AI/venv/lib/python3.12/site-packages/django/utils/deprecation.py", line 120, in __call__
    response = response or self.get_response(request)
                           ^^^^^^^^^^^^^^^^^^^^^^^^^^
  File "/home/ubuntu/Stackly_AI/venv/lib/python3.12/site-packages/django/core/handlers/exception.py", line 57, in inner
    response = response_for_exception(request, exc)
               ^^^^^^^^^^^^^^^^^^^^^^^^^^^^^^^^^^^^
  File "/home/ubuntu/Stackly_AI/venv/lib/python3.12/site-packages/django/core/handlers/exception.py", line 141, in response_for_exception
    response = handle_uncaught_exception(
               ^^^^^^^^^^^^^^^^^^^^^^^^^^
  File "/home/ubuntu/Stackly_AI/venv/lib/python3.12/site-packages/django/core/handlers/exception.py", line 182, in handle_uncaught_exception
    return debug.technical_500_response(request, *exc_info)
           ^^^^^^^^^^^^^^^^^^^^^^^^^^^^^^^^^^^^^^^^^^^^^^^^
  File "/home/ubuntu/Stackly_AI/venv/lib/python3.12/site-packages/django/views/debug.py", line 69, in technical_500_response
    html = reporter.get_traceback_html()
           ^^^^^^^^^^^^^^^^^^^^^^^^^^^^^
  File "/home/ubuntu/Stackly_AI/venv/lib/python3.12/site-packages/django/views/debug.py", line 428, in get_traceback_html
    c = Context(self.get_traceback_data(), use_l10n=False)
                ^^^^^^^^^^^^^^^^^^^^^^^^^
  File "/home/ubuntu/Stackly_AI/venv/lib/python3.12/site-packages/django/views/debug.py", line 397, in get_traceback_data
    "settings": self.filter.get_safe_settings(),
                ^^^^^^^^^^^^^^^^^^^^^^^^^^^^^^^
  File "/home/ubuntu/Stackly_AI/venv/lib/python3.12/site-packages/django/views/debug.py", line 156, in get_safe_settings
    settings_dict[k] = self.cleanse_setting(k, getattr(settings, k))
                                               ^^^^^^^^^^^^^^^^^^^^
  File "/home/ubuntu/Stackly_AI/venv/lib/python3.12/site-packages/django/conf/__init__.py", line 90, in __getattr__
    raise ImproperlyConfigured("The SECRET_KEY setting must not be empty.")
django.core.exceptions.ImproperlyConfigured: The SECRET_KEY setting must not be empty.

During handling of the above exception, another exception occurred:

Traceback (most recent call last):
  File "/home/ubuntu/Stackly_AI/venv/lib/python3.12/site-packages/django/core/handlers/exception.py", line 55, in inner
    response = get_response(request)
               ^^^^^^^^^^^^^^^^^^^^^
  File "/home/ubuntu/Stackly_AI/venv/lib/python3.12/site-packages/django/utils/deprecation.py", line 120, in __call__
    response = response or self.get_response(request)
                           ^^^^^^^^^^^^^^^^^^^^^^^^^^
  File "/home/ubuntu/Stackly_AI/venv/lib/python3.12/site-packages/django/core/handlers/exception.py", line 57, in inner
    response = response_for_exception(request, exc)
               ^^^^^^^^^^^^^^^^^^^^^^^^^^^^^^^^^^^^
  File "/home/ubuntu/Stackly_AI/venv/lib/python3.12/site-packages/django/core/handlers/exception.py", line 141, in response_for_exception
    response = handle_uncaught_exception(
               ^^^^^^^^^^^^^^^^^^^^^^^^^^
  File "/home/ubuntu/Stackly_AI/venv/lib/python3.12/site-packages/django/core/handlers/exception.py", line 182, in handle_uncaught_exception
    return debug.technical_500_response(request, *exc_info)
           ^^^^^^^^^^^^^^^^^^^^^^^^^^^^^^^^^^^^^^^^^^^^^^^^
  File "/home/ubuntu/Stackly_AI/venv/lib/python3.12/site-packages/django/views/debug.py", line 69, in technical_500_response
    html = reporter.get_traceback_html()
           ^^^^^^^^^^^^^^^^^^^^^^^^^^^^^
  File "/home/ubuntu/Stackly_AI/venv/lib/python3.12/site-packages/django/views/debug.py", line 428, in get_traceback_html
    c = Context(self.get_traceback_data(), use_l10n=False)
                ^^^^^^^^^^^^^^^^^^^^^^^^^
  File "/home/ubuntu/Stackly_AI/venv/lib/python3.12/site-packages/django/views/debug.py", line 397, in get_traceback_data
    "settings": self.filter.get_safe_settings(),
                ^^^^^^^^^^^^^^^^^^^^^^^^^^^^^^^
  File "/home/ubuntu/Stackly_AI/venv/lib/python3.12/site-packages/django/views/debug.py", line 156, in get_safe_settings
    settings_dict[k] = self.cleanse_setting(k, getattr(settings, k))
                                               ^^^^^^^^^^^^^^^^^^^^
  File "/home/ubuntu/Stackly_AI/venv/lib/python3.12/site-packages/django/conf/__init__.py", line 90, in __getattr__
    raise ImproperlyConfigured("The SECRET_KEY setting must not be empty.")
django.core.exceptions.ImproperlyConfigured: The SECRET_KEY setting must not be empty.

During handling of the above exception, another exception occurred:

Traceback (most recent call last):
  File "/home/ubuntu/Stackly_AI/venv/lib/python3.12/site-packages/django/core/handlers/exception.py", line 55, in inner
    response = get_response(request)
               ^^^^^^^^^^^^^^^^^^^^^
  File "/home/ubuntu/Stackly_AI/venv/lib/python3.12/site-packages/django/utils/deprecation.py", line 120, in __call__
    response = response or self.get_response(request)
                           ^^^^^^^^^^^^^^^^^^^^^^^^^^
  File "/home/ubuntu/Stackly_AI/venv/lib/python3.12/site-packages/django/core/handlers/exception.py", line 57, in inner
    response = response_for_exception(request, exc)
               ^^^^^^^^^^^^^^^^^^^^^^^^^^^^^^^^^^^^
  File "/home/ubuntu/Stackly_AI/venv/lib/python3.12/site-packages/django/core/handlers/exception.py", line 141, in response_for_exception
    response = handle_uncaught_exception(
               ^^^^^^^^^^^^^^^^^^^^^^^^^^
  File "/home/ubuntu/Stackly_AI/venv/lib/python3.12/site-packages/django/core/handlers/exception.py", line 182, in handle_uncaught_exception
    return debug.technical_500_response(request, *exc_info)
           ^^^^^^^^^^^^^^^^^^^^^^^^^^^^^^^^^^^^^^^^^^^^^^^^
  File "/home/ubuntu/Stackly_AI/venv/lib/python3.12/site-packages/django/views/debug.py", line 69, in technical_500_response
    html = reporter.get_traceback_html()
           ^^^^^^^^^^^^^^^^^^^^^^^^^^^^^
  File "/home/ubuntu/Stackly_AI/venv/lib/python3.12/site-packages/django/views/debug.py", line 428, in get_traceback_html
    c = Context(self.get_traceback_data(), use_l10n=False)
                ^^^^^^^^^^^^^^^^^^^^^^^^^
  File "/home/ubuntu/Stackly_AI/venv/lib/python3.12/site-packages/django/views/debug.py", line 397, in get_traceback_data
    "settings": self.filter.get_safe_settings(),
                ^^^^^^^^^^^^^^^^^^^^^^^^^^^^^^^
  File "/home/ubuntu/Stackly_AI/venv/lib/python3.12/site-packages/django/views/debug.py", line 156, in get_safe_settings
    settings_dict[k] = self.cleanse_setting(k, getattr(settings, k))
                                               ^^^^^^^^^^^^^^^^^^^^
  File "/home/ubuntu/Stackly_AI/venv/lib/python3.12/site-packages/django/conf/__init__.py", line 90, in __getattr__
    raise ImproperlyConfigured("The SECRET_KEY setting must not be empty.")
django.core.exceptions.ImproperlyConfigured: The SECRET_KEY setting must not be empty.

During handling of the above exception, another exception occurred:

Traceback (most recent call last):
  File "/home/ubuntu/Stackly_AI/venv/lib/python3.12/site-packages/gunicorn/workers/sync.py", line 135, in handle
    self.handle_request(listener, req, client, addr)
  File "/home/ubuntu/Stackly_AI/venv/lib/python3.12/site-packages/gunicorn/workers/sync.py", line 178, in handle_request
    respiter = self.wsgi(environ, resp.start_response)
               ^^^^^^^^^^^^^^^^^^^^^^^^^^^^^^^^^^^^^^^
  File "/home/ubuntu/Stackly_AI/venv/lib/python3.12/site-packages/django/core/handlers/wsgi.py", line 124, in __call__
    response = self.get_response(request)
               ^^^^^^^^^^^^^^^^^^^^^^^^^^
  File "/home/ubuntu/Stackly_AI/venv/lib/python3.12/site-packages/django/core/handlers/base.py", line 140, in get_response
    response = self._middleware_chain(request)
               ^^^^^^^^^^^^^^^^^^^^^^^^^^^^^^^
  File "/home/ubuntu/Stackly_AI/venv/lib/python3.12/site-packages/django/core/handlers/exception.py", line 57, in inner
    response = response_for_exception(request, exc)
               ^^^^^^^^^^^^^^^^^^^^^^^^^^^^^^^^^^^^
  File "/home/ubuntu/Stackly_AI/venv/lib/python3.12/site-packages/django/core/handlers/exception.py", line 141, in response_for_exception
    response = handle_uncaught_exception(
               ^^^^^^^^^^^^^^^^^^^^^^^^^^
  File "/home/ubuntu/Stackly_AI/venv/lib/python3.12/site-packages/django/core/handlers/exception.py", line 182, in handle_uncaught_exception
    return debug.technical_500_response(request, *exc_info)
           ^^^^^^^^^^^^^^^^^^^^^^^^^^^^^^^^^^^^^^^^^^^^^^^^
  File "/home/ubuntu/Stackly_AI/venv/lib/python3.12/site-packages/django/views/debug.py", line 69, in technical_500_response
    html = reporter.get_traceback_html()
           ^^^^^^^^^^^^^^^^^^^^^^^^^^^^^
  File "/home/ubuntu/Stackly_AI/venv/lib/python3.12/site-packages/django/views/debug.py", line 428, in get_traceback_html
    c = Context(self.get_traceback_data(), use_l10n=False)
                ^^^^^^^^^^^^^^^^^^^^^^^^^
  File "/home/ubuntu/Stackly_AI/venv/lib/python3.12/site-packages/django/views/debug.py", line 397, in get_traceback_data
    "settings": self.filter.get_safe_settings(),
                ^^^^^^^^^^^^^^^^^^^^^^^^^^^^^^^
  File "/home/ubuntu/Stackly_AI/venv/lib/python3.12/site-packages/django/views/debug.py", line 156, in get_safe_settings
    settings_dict[k] = self.cleanse_setting(k, getattr(settings, k))
                                               ^^^^^^^^^^^^^^^^^^^^
  File "/home/ubuntu/Stackly_AI/venv/lib/python3.12/site-packages/django/conf/__init__.py", line 90, in __getattr__
    raise ImproperlyConfigured("The SECRET_KEY setting must not be empty.")
django.core.exceptions.ImproperlyConfigured: The SECRET_KEY setting must not be empty.
[2025-10-13 14:04:43 +0000] [9678] [ERROR] Error handling request /
Traceback (most recent call last):
  File "/home/ubuntu/Stackly_AI/venv/lib/python3.12/site-packages/django/core/handlers/exception.py", line 55, in inner
    response = get_response(request)
               ^^^^^^^^^^^^^^^^^^^^^
  File "/home/ubuntu/Stackly_AI/venv/lib/python3.12/site-packages/django/utils/deprecation.py", line 119, in __call__
    response = self.process_request(request)
               ^^^^^^^^^^^^^^^^^^^^^^^^^^^^^
  File "/home/ubuntu/Stackly_AI/venv/lib/python3.12/site-packages/django/contrib/messages/middleware.py", line 12, in process_request
    request._messages = default_storage(request)
                        ^^^^^^^^^^^^^^^^^^^^^^^^
  File "/home/ubuntu/Stackly_AI/venv/lib/python3.12/site-packages/django/contrib/messages/storage/__init__.py", line 12, in default_storage
    return import_string(settings.MESSAGE_STORAGE)(request)
           ^^^^^^^^^^^^^^^^^^^^^^^^^^^^^^^^^^^^^^^^^^^^^^^^
  File "/home/ubuntu/Stackly_AI/venv/lib/python3.12/site-packages/django/contrib/messages/storage/fallback.py", line 17, in __init__
    storage_class(*args, **kwargs) for storage_class in self.storage_classes
    ^^^^^^^^^^^^^^^^^^^^^^^^^^^^^^
  File "/home/ubuntu/Stackly_AI/venv/lib/python3.12/site-packages/django/contrib/messages/storage/cookie.py", line 92, in __init__
    self.signer = signing.get_cookie_signer(salt=self.key_salt)
                  ^^^^^^^^^^^^^^^^^^^^^^^^^^^^^^^^^^^^^^^^^^^^^
  File "/home/ubuntu/Stackly_AI/venv/lib/python3.12/site-packages/django/core/signing.py", line 112, in get_cookie_signer
    key=_cookie_signer_key(settings.SECRET_KEY),
                           ^^^^^^^^^^^^^^^^^^^
  File "/home/ubuntu/Stackly_AI/venv/lib/python3.12/site-packages/django/conf/__init__.py", line 90, in __getattr__
    raise ImproperlyConfigured("The SECRET_KEY setting must not be empty.")
django.core.exceptions.ImproperlyConfigured: The SECRET_KEY setting must not be empty.

During handling of the above exception, another exception occurred:

Traceback (most recent call last):
  File "/home/ubuntu/Stackly_AI/venv/lib/python3.12/site-packages/django/core/handlers/exception.py", line 55, in inner
    response = get_response(request)
               ^^^^^^^^^^^^^^^^^^^^^
  File "/home/ubuntu/Stackly_AI/venv/lib/python3.12/site-packages/django/utils/deprecation.py", line 120, in __call__
    response = response or self.get_response(request)
                           ^^^^^^^^^^^^^^^^^^^^^^^^^^
  File "/home/ubuntu/Stackly_AI/venv/lib/python3.12/site-packages/django/core/handlers/exception.py", line 57, in inner
    response = response_for_exception(request, exc)
               ^^^^^^^^^^^^^^^^^^^^^^^^^^^^^^^^^^^^
  File "/home/ubuntu/Stackly_AI/venv/lib/python3.12/site-packages/django/core/handlers/exception.py", line 141, in response_for_exception
    response = handle_uncaught_exception(
               ^^^^^^^^^^^^^^^^^^^^^^^^^^
  File "/home/ubuntu/Stackly_AI/venv/lib/python3.12/site-packages/django/core/handlers/exception.py", line 182, in handle_uncaught_exception
    return debug.technical_500_response(request, *exc_info)
           ^^^^^^^^^^^^^^^^^^^^^^^^^^^^^^^^^^^^^^^^^^^^^^^^
  File "/home/ubuntu/Stackly_AI/venv/lib/python3.12/site-packages/django/views/debug.py", line 69, in technical_500_response
    html = reporter.get_traceback_html()
           ^^^^^^^^^^^^^^^^^^^^^^^^^^^^^
  File "/home/ubuntu/Stackly_AI/venv/lib/python3.12/site-packages/django/views/debug.py", line 428, in get_traceback_html
    c = Context(self.get_traceback_data(), use_l10n=False)
                ^^^^^^^^^^^^^^^^^^^^^^^^^
  File "/home/ubuntu/Stackly_AI/venv/lib/python3.12/site-packages/django/views/debug.py", line 397, in get_traceback_data
    "settings": self.filter.get_safe_settings(),
                ^^^^^^^^^^^^^^^^^^^^^^^^^^^^^^^
  File "/home/ubuntu/Stackly_AI/venv/lib/python3.12/site-packages/django/views/debug.py", line 156, in get_safe_settings
    settings_dict[k] = self.cleanse_setting(k, getattr(settings, k))
                                               ^^^^^^^^^^^^^^^^^^^^
  File "/home/ubuntu/Stackly_AI/venv/lib/python3.12/site-packages/django/conf/__init__.py", line 90, in __getattr__
    raise ImproperlyConfigured("The SECRET_KEY setting must not be empty.")
django.core.exceptions.ImproperlyConfigured: The SECRET_KEY setting must not be empty.

During handling of the above exception, another exception occurred:

Traceback (most recent call last):
  File "/home/ubuntu/Stackly_AI/venv/lib/python3.12/site-packages/django/core/handlers/exception.py", line 55, in inner
    response = get_response(request)
               ^^^^^^^^^^^^^^^^^^^^^
  File "/home/ubuntu/Stackly_AI/venv/lib/python3.12/site-packages/django/utils/deprecation.py", line 120, in __call__
    response = response or self.get_response(request)
                           ^^^^^^^^^^^^^^^^^^^^^^^^^^
  File "/home/ubuntu/Stackly_AI/venv/lib/python3.12/site-packages/django/core/handlers/exception.py", line 57, in inner
    response = response_for_exception(request, exc)
               ^^^^^^^^^^^^^^^^^^^^^^^^^^^^^^^^^^^^
  File "/home/ubuntu/Stackly_AI/venv/lib/python3.12/site-packages/django/core/handlers/exception.py", line 141, in response_for_exception
    response = handle_uncaught_exception(
               ^^^^^^^^^^^^^^^^^^^^^^^^^^
  File "/home/ubuntu/Stackly_AI/venv/lib/python3.12/site-packages/django/core/handlers/exception.py", line 182, in handle_uncaught_exception
    return debug.technical_500_response(request, *exc_info)
           ^^^^^^^^^^^^^^^^^^^^^^^^^^^^^^^^^^^^^^^^^^^^^^^^
  File "/home/ubuntu/Stackly_AI/venv/lib/python3.12/site-packages/django/views/debug.py", line 69, in technical_500_response
    html = reporter.get_traceback_html()
           ^^^^^^^^^^^^^^^^^^^^^^^^^^^^^
  File "/home/ubuntu/Stackly_AI/venv/lib/python3.12/site-packages/django/views/debug.py", line 428, in get_traceback_html
    c = Context(self.get_traceback_data(), use_l10n=False)
                ^^^^^^^^^^^^^^^^^^^^^^^^^
  File "/home/ubuntu/Stackly_AI/venv/lib/python3.12/site-packages/django/views/debug.py", line 397, in get_traceback_data
    "settings": self.filter.get_safe_settings(),
                ^^^^^^^^^^^^^^^^^^^^^^^^^^^^^^^
  File "/home/ubuntu/Stackly_AI/venv/lib/python3.12/site-packages/django/views/debug.py", line 156, in get_safe_settings
    settings_dict[k] = self.cleanse_setting(k, getattr(settings, k))
                                               ^^^^^^^^^^^^^^^^^^^^
  File "/home/ubuntu/Stackly_AI/venv/lib/python3.12/site-packages/django/conf/__init__.py", line 90, in __getattr__
    raise ImproperlyConfigured("The SECRET_KEY setting must not be empty.")
django.core.exceptions.ImproperlyConfigured: The SECRET_KEY setting must not be empty.

During handling of the above exception, another exception occurred:

Traceback (most recent call last):
  File "/home/ubuntu/Stackly_AI/venv/lib/python3.12/site-packages/django/core/handlers/exception.py", line 55, in inner
    response = get_response(request)
               ^^^^^^^^^^^^^^^^^^^^^
  File "/home/ubuntu/Stackly_AI/venv/lib/python3.12/site-packages/django/utils/deprecation.py", line 120, in __call__
    response = response or self.get_response(request)
                           ^^^^^^^^^^^^^^^^^^^^^^^^^^
  File "/home/ubuntu/Stackly_AI/venv/lib/python3.12/site-packages/django/core/handlers/exception.py", line 57, in inner
    response = response_for_exception(request, exc)
               ^^^^^^^^^^^^^^^^^^^^^^^^^^^^^^^^^^^^
  File "/home/ubuntu/Stackly_AI/venv/lib/python3.12/site-packages/django/core/handlers/exception.py", line 141, in response_for_exception
    response = handle_uncaught_exception(
               ^^^^^^^^^^^^^^^^^^^^^^^^^^
  File "/home/ubuntu/Stackly_AI/venv/lib/python3.12/site-packages/django/core/handlers/exception.py", line 182, in handle_uncaught_exception
    return debug.technical_500_response(request, *exc_info)
           ^^^^^^^^^^^^^^^^^^^^^^^^^^^^^^^^^^^^^^^^^^^^^^^^
  File "/home/ubuntu/Stackly_AI/venv/lib/python3.12/site-packages/django/views/debug.py", line 69, in technical_500_response
    html = reporter.get_traceback_html()
           ^^^^^^^^^^^^^^^^^^^^^^^^^^^^^
  File "/home/ubuntu/Stackly_AI/venv/lib/python3.12/site-packages/django/views/debug.py", line 428, in get_traceback_html
    c = Context(self.get_traceback_data(), use_l10n=False)
                ^^^^^^^^^^^^^^^^^^^^^^^^^
  File "/home/ubuntu/Stackly_AI/venv/lib/python3.12/site-packages/django/views/debug.py", line 397, in get_traceback_data
    "settings": self.filter.get_safe_settings(),
                ^^^^^^^^^^^^^^^^^^^^^^^^^^^^^^^
  File "/home/ubuntu/Stackly_AI/venv/lib/python3.12/site-packages/django/views/debug.py", line 156, in get_safe_settings
    settings_dict[k] = self.cleanse_setting(k, getattr(settings, k))
                                               ^^^^^^^^^^^^^^^^^^^^
  File "/home/ubuntu/Stackly_AI/venv/lib/python3.12/site-packages/django/conf/__init__.py", line 90, in __getattr__
    raise ImproperlyConfigured("The SECRET_KEY setting must not be empty.")
django.core.exceptions.ImproperlyConfigured: The SECRET_KEY setting must not be empty.

During handling of the above exception, another exception occurred:

Traceback (most recent call last):
  File "/home/ubuntu/Stackly_AI/venv/lib/python3.12/site-packages/django/core/handlers/exception.py", line 55, in inner
    response = get_response(request)
               ^^^^^^^^^^^^^^^^^^^^^
  File "/home/ubuntu/Stackly_AI/venv/lib/python3.12/site-packages/django/utils/deprecation.py", line 120, in __call__
    response = response or self.get_response(request)
                           ^^^^^^^^^^^^^^^^^^^^^^^^^^
  File "/home/ubuntu/Stackly_AI/venv/lib/python3.12/site-packages/django/core/handlers/exception.py", line 57, in inner
    response = response_for_exception(request, exc)
               ^^^^^^^^^^^^^^^^^^^^^^^^^^^^^^^^^^^^
  File "/home/ubuntu/Stackly_AI/venv/lib/python3.12/site-packages/django/core/handlers/exception.py", line 141, in response_for_exception
    response = handle_uncaught_exception(
               ^^^^^^^^^^^^^^^^^^^^^^^^^^
  File "/home/ubuntu/Stackly_AI/venv/lib/python3.12/site-packages/django/core/handlers/exception.py", line 182, in handle_uncaught_exception
    return debug.technical_500_response(request, *exc_info)
           ^^^^^^^^^^^^^^^^^^^^^^^^^^^^^^^^^^^^^^^^^^^^^^^^
  File "/home/ubuntu/Stackly_AI/venv/lib/python3.12/site-packages/django/views/debug.py", line 69, in technical_500_response
    html = reporter.get_traceback_html()
           ^^^^^^^^^^^^^^^^^^^^^^^^^^^^^
  File "/home/ubuntu/Stackly_AI/venv/lib/python3.12/site-packages/django/views/debug.py", line 428, in get_traceback_html
    c = Context(self.get_traceback_data(), use_l10n=False)
                ^^^^^^^^^^^^^^^^^^^^^^^^^
  File "/home/ubuntu/Stackly_AI/venv/lib/python3.12/site-packages/django/views/debug.py", line 397, in get_traceback_data
    "settings": self.filter.get_safe_settings(),
                ^^^^^^^^^^^^^^^^^^^^^^^^^^^^^^^
  File "/home/ubuntu/Stackly_AI/venv/lib/python3.12/site-packages/django/views/debug.py", line 156, in get_safe_settings
    settings_dict[k] = self.cleanse_setting(k, getattr(settings, k))
                                               ^^^^^^^^^^^^^^^^^^^^
  File "/home/ubuntu/Stackly_AI/venv/lib/python3.12/site-packages/django/conf/__init__.py", line 90, in __getattr__
    raise ImproperlyConfigured("The SECRET_KEY setting must not be empty.")
django.core.exceptions.ImproperlyConfigured: The SECRET_KEY setting must not be empty.

During handling of the above exception, another exception occurred:

Traceback (most recent call last):
  File "/home/ubuntu/Stackly_AI/venv/lib/python3.12/site-packages/django/core/handlers/exception.py", line 55, in inner
    response = get_response(request)
               ^^^^^^^^^^^^^^^^^^^^^
  File "/home/ubuntu/Stackly_AI/venv/lib/python3.12/site-packages/django/utils/deprecation.py", line 120, in __call__
    response = response or self.get_response(request)
                           ^^^^^^^^^^^^^^^^^^^^^^^^^^
  File "/home/ubuntu/Stackly_AI/venv/lib/python3.12/site-packages/django/core/handlers/exception.py", line 57, in inner
    response = response_for_exception(request, exc)
               ^^^^^^^^^^^^^^^^^^^^^^^^^^^^^^^^^^^^
  File "/home/ubuntu/Stackly_AI/venv/lib/python3.12/site-packages/django/core/handlers/exception.py", line 141, in response_for_exception
    response = handle_uncaught_exception(
               ^^^^^^^^^^^^^^^^^^^^^^^^^^
  File "/home/ubuntu/Stackly_AI/venv/lib/python3.12/site-packages/django/core/handlers/exception.py", line 182, in handle_uncaught_exception
    return debug.technical_500_response(request, *exc_info)
           ^^^^^^^^^^^^^^^^^^^^^^^^^^^^^^^^^^^^^^^^^^^^^^^^
  File "/home/ubuntu/Stackly_AI/venv/lib/python3.12/site-packages/django/views/debug.py", line 69, in technical_500_response
    html = reporter.get_traceback_html()
           ^^^^^^^^^^^^^^^^^^^^^^^^^^^^^
  File "/home/ubuntu/Stackly_AI/venv/lib/python3.12/site-packages/django/views/debug.py", line 428, in get_traceback_html
    c = Context(self.get_traceback_data(), use_l10n=False)
                ^^^^^^^^^^^^^^^^^^^^^^^^^
  File "/home/ubuntu/Stackly_AI/venv/lib/python3.12/site-packages/django/views/debug.py", line 397, in get_traceback_data
    "settings": self.filter.get_safe_settings(),
                ^^^^^^^^^^^^^^^^^^^^^^^^^^^^^^^
  File "/home/ubuntu/Stackly_AI/venv/lib/python3.12/site-packages/django/views/debug.py", line 156, in get_safe_settings
    settings_dict[k] = self.cleanse_setting(k, getattr(settings, k))
                                               ^^^^^^^^^^^^^^^^^^^^
  File "/home/ubuntu/Stackly_AI/venv/lib/python3.12/site-packages/django/conf/__init__.py", line 90, in __getattr__
    raise ImproperlyConfigured("The SECRET_KEY setting must not be empty.")
django.core.exceptions.ImproperlyConfigured: The SECRET_KEY setting must not be empty.

During handling of the above exception, another exception occurred:

Traceback (most recent call last):
  File "/home/ubuntu/Stackly_AI/venv/lib/python3.12/site-packages/gunicorn/workers/sync.py", line 135, in handle
    self.handle_request(listener, req, client, addr)
  File "/home/ubuntu/Stackly_AI/venv/lib/python3.12/site-packages/gunicorn/workers/sync.py", line 178, in handle_request
    respiter = self.wsgi(environ, resp.start_response)
               ^^^^^^^^^^^^^^^^^^^^^^^^^^^^^^^^^^^^^^^
  File "/home/ubuntu/Stackly_AI/venv/lib/python3.12/site-packages/django/core/handlers/wsgi.py", line 124, in __call__
    response = self.get_response(request)
               ^^^^^^^^^^^^^^^^^^^^^^^^^^
  File "/home/ubuntu/Stackly_AI/venv/lib/python3.12/site-packages/django/core/handlers/base.py", line 140, in get_response
    response = self._middleware_chain(request)
               ^^^^^^^^^^^^^^^^^^^^^^^^^^^^^^^
  File "/home/ubuntu/Stackly_AI/venv/lib/python3.12/site-packages/django/core/handlers/exception.py", line 57, in inner
    response = response_for_exception(request, exc)
               ^^^^^^^^^^^^^^^^^^^^^^^^^^^^^^^^^^^^
  File "/home/ubuntu/Stackly_AI/venv/lib/python3.12/site-packages/django/core/handlers/exception.py", line 141, in response_for_exception
    response = handle_uncaught_exception(
               ^^^^^^^^^^^^^^^^^^^^^^^^^^
  File "/home/ubuntu/Stackly_AI/venv/lib/python3.12/site-packages/django/core/handlers/exception.py", line 182, in handle_uncaught_exception
    return debug.technical_500_response(request, *exc_info)
           ^^^^^^^^^^^^^^^^^^^^^^^^^^^^^^^^^^^^^^^^^^^^^^^^
  File "/home/ubuntu/Stackly_AI/venv/lib/python3.12/site-packages/django/views/debug.py", line 69, in technical_500_response
    html = reporter.get_traceback_html()
           ^^^^^^^^^^^^^^^^^^^^^^^^^^^^^
  File "/home/ubuntu/Stackly_AI/venv/lib/python3.12/site-packages/django/views/debug.py", line 428, in get_traceback_html
    c = Context(self.get_traceback_data(), use_l10n=False)
                ^^^^^^^^^^^^^^^^^^^^^^^^^
  File "/home/ubuntu/Stackly_AI/venv/lib/python3.12/site-packages/django/views/debug.py", line 397, in get_traceback_data
    "settings": self.filter.get_safe_settings(),
                ^^^^^^^^^^^^^^^^^^^^^^^^^^^^^^^
  File "/home/ubuntu/Stackly_AI/venv/lib/python3.12/site-packages/django/views/debug.py", line 156, in get_safe_settings
    settings_dict[k] = self.cleanse_setting(k, getattr(settings, k))
                                               ^^^^^^^^^^^^^^^^^^^^
  File "/home/ubuntu/Stackly_AI/venv/lib/python3.12/site-packages/django/conf/__init__.py", line 90, in __getattr__
    raise ImproperlyConfigured("The SECRET_KEY setting must not be empty.")
django.core.exceptions.ImproperlyConfigured: The SECRET_KEY setting must not be empty.
[2025-10-13 14:04:43 +0000] [9679] [ERROR] Error handling request /favicon.ico
Traceback (most recent call last):
  File "/home/ubuntu/Stackly_AI/venv/lib/python3.12/site-packages/django/core/handlers/exception.py", line 55, in inner
    response = get_response(request)
               ^^^^^^^^^^^^^^^^^^^^^
  File "/home/ubuntu/Stackly_AI/venv/lib/python3.12/site-packages/django/utils/deprecation.py", line 119, in __call__
    response = self.process_request(request)
               ^^^^^^^^^^^^^^^^^^^^^^^^^^^^^
  File "/home/ubuntu/Stackly_AI/venv/lib/python3.12/site-packages/django/contrib/messages/middleware.py", line 12, in process_request
    request._messages = default_storage(request)
                        ^^^^^^^^^^^^^^^^^^^^^^^^
  File "/home/ubuntu/Stackly_AI/venv/lib/python3.12/site-packages/django/contrib/messages/storage/__init__.py", line 12, in default_storage
    return import_string(settings.MESSAGE_STORAGE)(request)
           ^^^^^^^^^^^^^^^^^^^^^^^^^^^^^^^^^^^^^^^^^^^^^^^^
  File "/home/ubuntu/Stackly_AI/venv/lib/python3.12/site-packages/django/contrib/messages/storage/fallback.py", line 17, in __init__
    storage_class(*args, **kwargs) for storage_class in self.storage_classes
    ^^^^^^^^^^^^^^^^^^^^^^^^^^^^^^
  File "/home/ubuntu/Stackly_AI/venv/lib/python3.12/site-packages/django/contrib/messages/storage/cookie.py", line 92, in __init__
    self.signer = signing.get_cookie_signer(salt=self.key_salt)
                  ^^^^^^^^^^^^^^^^^^^^^^^^^^^^^^^^^^^^^^^^^^^^^
  File "/home/ubuntu/Stackly_AI/venv/lib/python3.12/site-packages/django/core/signing.py", line 112, in get_cookie_signer
    key=_cookie_signer_key(settings.SECRET_KEY),
                           ^^^^^^^^^^^^^^^^^^^
  File "/home/ubuntu/Stackly_AI/venv/lib/python3.12/site-packages/django/conf/__init__.py", line 90, in __getattr__
    raise ImproperlyConfigured("The SECRET_KEY setting must not be empty.")
django.core.exceptions.ImproperlyConfigured: The SECRET_KEY setting must not be empty.

During handling of the above exception, another exception occurred:

Traceback (most recent call last):
  File "/home/ubuntu/Stackly_AI/venv/lib/python3.12/site-packages/django/core/handlers/exception.py", line 55, in inner
    response = get_response(request)
               ^^^^^^^^^^^^^^^^^^^^^
  File "/home/ubuntu/Stackly_AI/venv/lib/python3.12/site-packages/django/utils/deprecation.py", line 120, in __call__
    response = response or self.get_response(request)
                           ^^^^^^^^^^^^^^^^^^^^^^^^^^
  File "/home/ubuntu/Stackly_AI/venv/lib/python3.12/site-packages/django/core/handlers/exception.py", line 57, in inner
    response = response_for_exception(request, exc)
               ^^^^^^^^^^^^^^^^^^^^^^^^^^^^^^^^^^^^
  File "/home/ubuntu/Stackly_AI/venv/lib/python3.12/site-packages/django/core/handlers/exception.py", line 141, in response_for_exception
    response = handle_uncaught_exception(
               ^^^^^^^^^^^^^^^^^^^^^^^^^^
  File "/home/ubuntu/Stackly_AI/venv/lib/python3.12/site-packages/django/core/handlers/exception.py", line 182, in handle_uncaught_exception
    return debug.technical_500_response(request, *exc_info)
           ^^^^^^^^^^^^^^^^^^^^^^^^^^^^^^^^^^^^^^^^^^^^^^^^
  File "/home/ubuntu/Stackly_AI/venv/lib/python3.12/site-packages/django/views/debug.py", line 69, in technical_500_response
    html = reporter.get_traceback_html()
           ^^^^^^^^^^^^^^^^^^^^^^^^^^^^^
  File "/home/ubuntu/Stackly_AI/venv/lib/python3.12/site-packages/django/views/debug.py", line 428, in get_traceback_html
    c = Context(self.get_traceback_data(), use_l10n=False)
                ^^^^^^^^^^^^^^^^^^^^^^^^^
  File "/home/ubuntu/Stackly_AI/venv/lib/python3.12/site-packages/django/views/debug.py", line 397, in get_traceback_data
    "settings": self.filter.get_safe_settings(),
                ^^^^^^^^^^^^^^^^^^^^^^^^^^^^^^^
  File "/home/ubuntu/Stackly_AI/venv/lib/python3.12/site-packages/django/views/debug.py", line 156, in get_safe_settings
    settings_dict[k] = self.cleanse_setting(k, getattr(settings, k))
                                               ^^^^^^^^^^^^^^^^^^^^
  File "/home/ubuntu/Stackly_AI/venv/lib/python3.12/site-packages/django/conf/__init__.py", line 90, in __getattr__
    raise ImproperlyConfigured("The SECRET_KEY setting must not be empty.")
django.core.exceptions.ImproperlyConfigured: The SECRET_KEY setting must not be empty.

During handling of the above exception, another exception occurred:

Traceback (most recent call last):
  File "/home/ubuntu/Stackly_AI/venv/lib/python3.12/site-packages/django/core/handlers/exception.py", line 55, in inner
    response = get_response(request)
               ^^^^^^^^^^^^^^^^^^^^^
  File "/home/ubuntu/Stackly_AI/venv/lib/python3.12/site-packages/django/utils/deprecation.py", line 120, in __call__
    response = response or self.get_response(request)
                           ^^^^^^^^^^^^^^^^^^^^^^^^^^
  File "/home/ubuntu/Stackly_AI/venv/lib/python3.12/site-packages/django/core/handlers/exception.py", line 57, in inner
    response = response_for_exception(request, exc)
               ^^^^^^^^^^^^^^^^^^^^^^^^^^^^^^^^^^^^
  File "/home/ubuntu/Stackly_AI/venv/lib/python3.12/site-packages/django/core/handlers/exception.py", line 141, in response_for_exception
    response = handle_uncaught_exception(
               ^^^^^^^^^^^^^^^^^^^^^^^^^^
  File "/home/ubuntu/Stackly_AI/venv/lib/python3.12/site-packages/django/core/handlers/exception.py", line 182, in handle_uncaught_exception
    return debug.technical_500_response(request, *exc_info)
           ^^^^^^^^^^^^^^^^^^^^^^^^^^^^^^^^^^^^^^^^^^^^^^^^
  File "/home/ubuntu/Stackly_AI/venv/lib/python3.12/site-packages/django/views/debug.py", line 69, in technical_500_response
    html = reporter.get_traceback_html()
           ^^^^^^^^^^^^^^^^^^^^^^^^^^^^^
  File "/home/ubuntu/Stackly_AI/venv/lib/python3.12/site-packages/django/views/debug.py", line 428, in get_traceback_html
    c = Context(self.get_traceback_data(), use_l10n=False)
                ^^^^^^^^^^^^^^^^^^^^^^^^^
  File "/home/ubuntu/Stackly_AI/venv/lib/python3.12/site-packages/django/views/debug.py", line 397, in get_traceback_data
    "settings": self.filter.get_safe_settings(),
                ^^^^^^^^^^^^^^^^^^^^^^^^^^^^^^^
  File "/home/ubuntu/Stackly_AI/venv/lib/python3.12/site-packages/django/views/debug.py", line 156, in get_safe_settings
    settings_dict[k] = self.cleanse_setting(k, getattr(settings, k))
                                               ^^^^^^^^^^^^^^^^^^^^
  File "/home/ubuntu/Stackly_AI/venv/lib/python3.12/site-packages/django/conf/__init__.py", line 90, in __getattr__
    raise ImproperlyConfigured("The SECRET_KEY setting must not be empty.")
django.core.exceptions.ImproperlyConfigured: The SECRET_KEY setting must not be empty.

During handling of the above exception, another exception occurred:

Traceback (most recent call last):
  File "/home/ubuntu/Stackly_AI/venv/lib/python3.12/site-packages/django/core/handlers/exception.py", line 55, in inner
    response = get_response(request)
               ^^^^^^^^^^^^^^^^^^^^^
  File "/home/ubuntu/Stackly_AI/venv/lib/python3.12/site-packages/django/utils/deprecation.py", line 120, in __call__
    response = response or self.get_response(request)
                           ^^^^^^^^^^^^^^^^^^^^^^^^^^
  File "/home/ubuntu/Stackly_AI/venv/lib/python3.12/site-packages/django/core/handlers/exception.py", line 57, in inner
    response = response_for_exception(request, exc)
               ^^^^^^^^^^^^^^^^^^^^^^^^^^^^^^^^^^^^
  File "/home/ubuntu/Stackly_AI/venv/lib/python3.12/site-packages/django/core/handlers/exception.py", line 141, in response_for_exception
    response = handle_uncaught_exception(
               ^^^^^^^^^^^^^^^^^^^^^^^^^^
  File "/home/ubuntu/Stackly_AI/venv/lib/python3.12/site-packages/django/core/handlers/exception.py", line 182, in handle_uncaught_exception
    return debug.technical_500_response(request, *exc_info)
           ^^^^^^^^^^^^^^^^^^^^^^^^^^^^^^^^^^^^^^^^^^^^^^^^
  File "/home/ubuntu/Stackly_AI/venv/lib/python3.12/site-packages/django/views/debug.py", line 69, in technical_500_response
    html = reporter.get_traceback_html()
           ^^^^^^^^^^^^^^^^^^^^^^^^^^^^^
  File "/home/ubuntu/Stackly_AI/venv/lib/python3.12/site-packages/django/views/debug.py", line 428, in get_traceback_html
    c = Context(self.get_traceback_data(), use_l10n=False)
                ^^^^^^^^^^^^^^^^^^^^^^^^^
  File "/home/ubuntu/Stackly_AI/venv/lib/python3.12/site-packages/django/views/debug.py", line 397, in get_traceback_data
    "settings": self.filter.get_safe_settings(),
                ^^^^^^^^^^^^^^^^^^^^^^^^^^^^^^^
  File "/home/ubuntu/Stackly_AI/venv/lib/python3.12/site-packages/django/views/debug.py", line 156, in get_safe_settings
    settings_dict[k] = self.cleanse_setting(k, getattr(settings, k))
                                               ^^^^^^^^^^^^^^^^^^^^
  File "/home/ubuntu/Stackly_AI/venv/lib/python3.12/site-packages/django/conf/__init__.py", line 90, in __getattr__
    raise ImproperlyConfigured("The SECRET_KEY setting must not be empty.")
django.core.exceptions.ImproperlyConfigured: The SECRET_KEY setting must not be empty.

During handling of the above exception, another exception occurred:

Traceback (most recent call last):
  File "/home/ubuntu/Stackly_AI/venv/lib/python3.12/site-packages/django/core/handlers/exception.py", line 55, in inner
    response = get_response(request)
               ^^^^^^^^^^^^^^^^^^^^^
  File "/home/ubuntu/Stackly_AI/venv/lib/python3.12/site-packages/django/utils/deprecation.py", line 120, in __call__
    response = response or self.get_response(request)
                           ^^^^^^^^^^^^^^^^^^^^^^^^^^
  File "/home/ubuntu/Stackly_AI/venv/lib/python3.12/site-packages/django/core/handlers/exception.py", line 57, in inner
    response = response_for_exception(request, exc)
               ^^^^^^^^^^^^^^^^^^^^^^^^^^^^^^^^^^^^
  File "/home/ubuntu/Stackly_AI/venv/lib/python3.12/site-packages/django/core/handlers/exception.py", line 141, in response_for_exception
    response = handle_uncaught_exception(
               ^^^^^^^^^^^^^^^^^^^^^^^^^^
  File "/home/ubuntu/Stackly_AI/venv/lib/python3.12/site-packages/django/core/handlers/exception.py", line 182, in handle_uncaught_exception
    return debug.technical_500_response(request, *exc_info)
           ^^^^^^^^^^^^^^^^^^^^^^^^^^^^^^^^^^^^^^^^^^^^^^^^
  File "/home/ubuntu/Stackly_AI/venv/lib/python3.12/site-packages/django/views/debug.py", line 69, in technical_500_response
    html = reporter.get_traceback_html()
           ^^^^^^^^^^^^^^^^^^^^^^^^^^^^^
  File "/home/ubuntu/Stackly_AI/venv/lib/python3.12/site-packages/django/views/debug.py", line 428, in get_traceback_html
    c = Context(self.get_traceback_data(), use_l10n=False)
                ^^^^^^^^^^^^^^^^^^^^^^^^^
  File "/home/ubuntu/Stackly_AI/venv/lib/python3.12/site-packages/django/views/debug.py", line 397, in get_traceback_data
    "settings": self.filter.get_safe_settings(),
                ^^^^^^^^^^^^^^^^^^^^^^^^^^^^^^^
  File "/home/ubuntu/Stackly_AI/venv/lib/python3.12/site-packages/django/views/debug.py", line 156, in get_safe_settings
    settings_dict[k] = self.cleanse_setting(k, getattr(settings, k))
                                               ^^^^^^^^^^^^^^^^^^^^
  File "/home/ubuntu/Stackly_AI/venv/lib/python3.12/site-packages/django/conf/__init__.py", line 90, in __getattr__
    raise ImproperlyConfigured("The SECRET_KEY setting must not be empty.")
django.core.exceptions.ImproperlyConfigured: The SECRET_KEY setting must not be empty.

During handling of the above exception, another exception occurred:

Traceback (most recent call last):
  File "/home/ubuntu/Stackly_AI/venv/lib/python3.12/site-packages/django/core/handlers/exception.py", line 55, in inner
    response = get_response(request)
               ^^^^^^^^^^^^^^^^^^^^^
  File "/home/ubuntu/Stackly_AI/venv/lib/python3.12/site-packages/django/utils/deprecation.py", line 120, in __call__
    response = response or self.get_response(request)
                           ^^^^^^^^^^^^^^^^^^^^^^^^^^
  File "/home/ubuntu/Stackly_AI/venv/lib/python3.12/site-packages/django/core/handlers/exception.py", line 57, in inner
    response = response_for_exception(request, exc)
               ^^^^^^^^^^^^^^^^^^^^^^^^^^^^^^^^^^^^
  File "/home/ubuntu/Stackly_AI/venv/lib/python3.12/site-packages/django/core/handlers/exception.py", line 141, in response_for_exception
    response = handle_uncaught_exception(
               ^^^^^^^^^^^^^^^^^^^^^^^^^^
  File "/home/ubuntu/Stackly_AI/venv/lib/python3.12/site-packages/django/core/handlers/exception.py", line 182, in handle_uncaught_exception
    return debug.technical_500_response(request, *exc_info)
           ^^^^^^^^^^^^^^^^^^^^^^^^^^^^^^^^^^^^^^^^^^^^^^^^
  File "/home/ubuntu/Stackly_AI/venv/lib/python3.12/site-packages/django/views/debug.py", line 69, in technical_500_response
    html = reporter.get_traceback_html()
           ^^^^^^^^^^^^^^^^^^^^^^^^^^^^^
  File "/home/ubuntu/Stackly_AI/venv/lib/python3.12/site-packages/django/views/debug.py", line 428, in get_traceback_html
    c = Context(self.get_traceback_data(), use_l10n=False)
                ^^^^^^^^^^^^^^^^^^^^^^^^^
  File "/home/ubuntu/Stackly_AI/venv/lib/python3.12/site-packages/django/views/debug.py", line 397, in get_traceback_data
    "settings": self.filter.get_safe_settings(),
                ^^^^^^^^^^^^^^^^^^^^^^^^^^^^^^^
  File "/home/ubuntu/Stackly_AI/venv/lib/python3.12/site-packages/django/views/debug.py", line 156, in get_safe_settings
    settings_dict[k] = self.cleanse_setting(k, getattr(settings, k))
                                               ^^^^^^^^^^^^^^^^^^^^
  File "/home/ubuntu/Stackly_AI/venv/lib/python3.12/site-packages/django/conf/__init__.py", line 90, in __getattr__
    raise ImproperlyConfigured("The SECRET_KEY setting must not be empty.")
django.core.exceptions.ImproperlyConfigured: The SECRET_KEY setting must not be empty.

During handling of the above exception, another exception occurred:

Traceback (most recent call last):
  File "/home/ubuntu/Stackly_AI/venv/lib/python3.12/site-packages/gunicorn/workers/sync.py", line 135, in handle
    self.handle_request(listener, req, client, addr)
  File "/home/ubuntu/Stackly_AI/venv/lib/python3.12/site-packages/gunicorn/workers/sync.py", line 178, in handle_request
    respiter = self.wsgi(environ, resp.start_response)
               ^^^^^^^^^^^^^^^^^^^^^^^^^^^^^^^^^^^^^^^
  File "/home/ubuntu/Stackly_AI/venv/lib/python3.12/site-packages/django/core/handlers/wsgi.py", line 124, in __call__
    response = self.get_response(request)
               ^^^^^^^^^^^^^^^^^^^^^^^^^^
  File "/home/ubuntu/Stackly_AI/venv/lib/python3.12/site-packages/django/core/handlers/base.py", line 140, in get_response
    response = self._middleware_chain(request)
               ^^^^^^^^^^^^^^^^^^^^^^^^^^^^^^^
  File "/home/ubuntu/Stackly_AI/venv/lib/python3.12/site-packages/django/core/handlers/exception.py", line 57, in inner
    response = response_for_exception(request, exc)
               ^^^^^^^^^^^^^^^^^^^^^^^^^^^^^^^^^^^^
  File "/home/ubuntu/Stackly_AI/venv/lib/python3.12/site-packages/django/core/handlers/exception.py", line 141, in response_for_exception
    response = handle_uncaught_exception(
               ^^^^^^^^^^^^^^^^^^^^^^^^^^
  File "/home/ubuntu/Stackly_AI/venv/lib/python3.12/site-packages/django/core/handlers/exception.py", line 182, in handle_uncaught_exception
    return debug.technical_500_response(request, *exc_info)
           ^^^^^^^^^^^^^^^^^^^^^^^^^^^^^^^^^^^^^^^^^^^^^^^^
  File "/home/ubuntu/Stackly_AI/venv/lib/python3.12/site-packages/django/views/debug.py", line 69, in technical_500_response
    html = reporter.get_traceback_html()
           ^^^^^^^^^^^^^^^^^^^^^^^^^^^^^
  File "/home/ubuntu/Stackly_AI/venv/lib/python3.12/site-packages/django/views/debug.py", line 428, in get_traceback_html
    c = Context(self.get_traceback_data(), use_l10n=False)
                ^^^^^^^^^^^^^^^^^^^^^^^^^
  File "/home/ubuntu/Stackly_AI/venv/lib/python3.12/site-packages/django/views/debug.py", line 397, in get_traceback_data
    "settings": self.filter.get_safe_settings(),
                ^^^^^^^^^^^^^^^^^^^^^^^^^^^^^^^
  File "/home/ubuntu/Stackly_AI/venv/lib/python3.12/site-packages/django/views/debug.py", line 156, in get_safe_settings
    settings_dict[k] = self.cleanse_setting(k, getattr(settings, k))
                                               ^^^^^^^^^^^^^^^^^^^^
  File "/home/ubuntu/Stackly_AI/venv/lib/python3.12/site-packages/django/conf/__init__.py", line 90, in __getattr__
    raise ImproperlyConfigured("The SECRET_KEY setting must not be empty.")
django.core.exceptions.ImproperlyConfigured: The SECRET_KEY setting must not be empty.
[2025-10-13 14:08:04 +0000] [9679] [ERROR] Error handling request /
Traceback (most recent call last):
  File "/home/ubuntu/Stackly_AI/venv/lib/python3.12/site-packages/django/core/handlers/exception.py", line 55, in inner
    response = get_response(request)
               ^^^^^^^^^^^^^^^^^^^^^
  File "/home/ubuntu/Stackly_AI/venv/lib/python3.12/site-packages/django/utils/deprecation.py", line 119, in __call__
    response = self.process_request(request)
               ^^^^^^^^^^^^^^^^^^^^^^^^^^^^^
  File "/home/ubuntu/Stackly_AI/venv/lib/python3.12/site-packages/django/contrib/messages/middleware.py", line 12, in process_request
    request._messages = default_storage(request)
                        ^^^^^^^^^^^^^^^^^^^^^^^^
  File "/home/ubuntu/Stackly_AI/venv/lib/python3.12/site-packages/django/contrib/messages/storage/__init__.py", line 12, in default_storage
    return import_string(settings.MESSAGE_STORAGE)(request)
           ^^^^^^^^^^^^^^^^^^^^^^^^^^^^^^^^^^^^^^^^^^^^^^^^
  File "/home/ubuntu/Stackly_AI/venv/lib/python3.12/site-packages/django/contrib/messages/storage/fallback.py", line 17, in __init__
    storage_class(*args, **kwargs) for storage_class in self.storage_classes
    ^^^^^^^^^^^^^^^^^^^^^^^^^^^^^^
  File "/home/ubuntu/Stackly_AI/venv/lib/python3.12/site-packages/django/contrib/messages/storage/cookie.py", line 92, in __init__
    self.signer = signing.get_cookie_signer(salt=self.key_salt)
                  ^^^^^^^^^^^^^^^^^^^^^^^^^^^^^^^^^^^^^^^^^^^^^
  File "/home/ubuntu/Stackly_AI/venv/lib/python3.12/site-packages/django/core/signing.py", line 112, in get_cookie_signer
    key=_cookie_signer_key(settings.SECRET_KEY),
                           ^^^^^^^^^^^^^^^^^^^
  File "/home/ubuntu/Stackly_AI/venv/lib/python3.12/site-packages/django/conf/__init__.py", line 90, in __getattr__
    raise ImproperlyConfigured("The SECRET_KEY setting must not be empty.")
django.core.exceptions.ImproperlyConfigured: The SECRET_KEY setting must not be empty.

During handling of the above exception, another exception occurred:

Traceback (most recent call last):
  File "/home/ubuntu/Stackly_AI/venv/lib/python3.12/site-packages/django/core/handlers/exception.py", line 55, in inner
    response = get_response(request)
               ^^^^^^^^^^^^^^^^^^^^^
  File "/home/ubuntu/Stackly_AI/venv/lib/python3.12/site-packages/django/utils/deprecation.py", line 120, in __call__
    response = response or self.get_response(request)
                           ^^^^^^^^^^^^^^^^^^^^^^^^^^
  File "/home/ubuntu/Stackly_AI/venv/lib/python3.12/site-packages/django/core/handlers/exception.py", line 57, in inner
    response = response_for_exception(request, exc)
               ^^^^^^^^^^^^^^^^^^^^^^^^^^^^^^^^^^^^
  File "/home/ubuntu/Stackly_AI/venv/lib/python3.12/site-packages/django/core/handlers/exception.py", line 141, in response_for_exception
    response = handle_uncaught_exception(
               ^^^^^^^^^^^^^^^^^^^^^^^^^^
  File "/home/ubuntu/Stackly_AI/venv/lib/python3.12/site-packages/django/core/handlers/exception.py", line 182, in handle_uncaught_exception
    return debug.technical_500_response(request, *exc_info)
           ^^^^^^^^^^^^^^^^^^^^^^^^^^^^^^^^^^^^^^^^^^^^^^^^
  File "/home/ubuntu/Stackly_AI/venv/lib/python3.12/site-packages/django/views/debug.py", line 69, in technical_500_response
    html = reporter.get_traceback_html()
           ^^^^^^^^^^^^^^^^^^^^^^^^^^^^^
  File "/home/ubuntu/Stackly_AI/venv/lib/python3.12/site-packages/django/views/debug.py", line 428, in get_traceback_html
    c = Context(self.get_traceback_data(), use_l10n=False)
                ^^^^^^^^^^^^^^^^^^^^^^^^^
  File "/home/ubuntu/Stackly_AI/venv/lib/python3.12/site-packages/django/views/debug.py", line 397, in get_traceback_data
    "settings": self.filter.get_safe_settings(),
                ^^^^^^^^^^^^^^^^^^^^^^^^^^^^^^^
  File "/home/ubuntu/Stackly_AI/venv/lib/python3.12/site-packages/django/views/debug.py", line 156, in get_safe_settings
    settings_dict[k] = self.cleanse_setting(k, getattr(settings, k))
                                               ^^^^^^^^^^^^^^^^^^^^
  File "/home/ubuntu/Stackly_AI/venv/lib/python3.12/site-packages/django/conf/__init__.py", line 90, in __getattr__
    raise ImproperlyConfigured("The SECRET_KEY setting must not be empty.")
django.core.exceptions.ImproperlyConfigured: The SECRET_KEY setting must not be empty.

During handling of the above exception, another exception occurred:

Traceback (most recent call last):
  File "/home/ubuntu/Stackly_AI/venv/lib/python3.12/site-packages/django/core/handlers/exception.py", line 55, in inner
    response = get_response(request)
               ^^^^^^^^^^^^^^^^^^^^^
  File "/home/ubuntu/Stackly_AI/venv/lib/python3.12/site-packages/django/utils/deprecation.py", line 120, in __call__
    response = response or self.get_response(request)
                           ^^^^^^^^^^^^^^^^^^^^^^^^^^
  File "/home/ubuntu/Stackly_AI/venv/lib/python3.12/site-packages/django/core/handlers/exception.py", line 57, in inner
    response = response_for_exception(request, exc)
               ^^^^^^^^^^^^^^^^^^^^^^^^^^^^^^^^^^^^
  File "/home/ubuntu/Stackly_AI/venv/lib/python3.12/site-packages/django/core/handlers/exception.py", line 141, in response_for_exception
    response = handle_uncaught_exception(
               ^^^^^^^^^^^^^^^^^^^^^^^^^^
  File "/home/ubuntu/Stackly_AI/venv/lib/python3.12/site-packages/django/core/handlers/exception.py", line 182, in handle_uncaught_exception
    return debug.technical_500_response(request, *exc_info)
           ^^^^^^^^^^^^^^^^^^^^^^^^^^^^^^^^^^^^^^^^^^^^^^^^
  File "/home/ubuntu/Stackly_AI/venv/lib/python3.12/site-packages/django/views/debug.py", line 69, in technical_500_response
    html = reporter.get_traceback_html()
           ^^^^^^^^^^^^^^^^^^^^^^^^^^^^^
  File "/home/ubuntu/Stackly_AI/venv/lib/python3.12/site-packages/django/views/debug.py", line 428, in get_traceback_html
    c = Context(self.get_traceback_data(), use_l10n=False)
                ^^^^^^^^^^^^^^^^^^^^^^^^^
  File "/home/ubuntu/Stackly_AI/venv/lib/python3.12/site-packages/django/views/debug.py", line 397, in get_traceback_data
    "settings": self.filter.get_safe_settings(),
                ^^^^^^^^^^^^^^^^^^^^^^^^^^^^^^^
  File "/home/ubuntu/Stackly_AI/venv/lib/python3.12/site-packages/django/views/debug.py", line 156, in get_safe_settings
    settings_dict[k] = self.cleanse_setting(k, getattr(settings, k))
                                               ^^^^^^^^^^^^^^^^^^^^
  File "/home/ubuntu/Stackly_AI/venv/lib/python3.12/site-packages/django/conf/__init__.py", line 90, in __getattr__
    raise ImproperlyConfigured("The SECRET_KEY setting must not be empty.")
django.core.exceptions.ImproperlyConfigured: The SECRET_KEY setting must not be empty.

During handling of the above exception, another exception occurred:

Traceback (most recent call last):
  File "/home/ubuntu/Stackly_AI/venv/lib/python3.12/site-packages/django/core/handlers/exception.py", line 55, in inner
    response = get_response(request)
               ^^^^^^^^^^^^^^^^^^^^^
  File "/home/ubuntu/Stackly_AI/venv/lib/python3.12/site-packages/django/utils/deprecation.py", line 120, in __call__
    response = response or self.get_response(request)
                           ^^^^^^^^^^^^^^^^^^^^^^^^^^
  File "/home/ubuntu/Stackly_AI/venv/lib/python3.12/site-packages/django/core/handlers/exception.py", line 57, in inner
    response = response_for_exception(request, exc)
               ^^^^^^^^^^^^^^^^^^^^^^^^^^^^^^^^^^^^
  File "/home/ubuntu/Stackly_AI/venv/lib/python3.12/site-packages/django/core/handlers/exception.py", line 141, in response_for_exception
    response = handle_uncaught_exception(
               ^^^^^^^^^^^^^^^^^^^^^^^^^^
  File "/home/ubuntu/Stackly_AI/venv/lib/python3.12/site-packages/django/core/handlers/exception.py", line 182, in handle_uncaught_exception
    return debug.technical_500_response(request, *exc_info)
           ^^^^^^^^^^^^^^^^^^^^^^^^^^^^^^^^^^^^^^^^^^^^^^^^
  File "/home/ubuntu/Stackly_AI/venv/lib/python3.12/site-packages/django/views/debug.py", line 69, in technical_500_response
    html = reporter.get_traceback_html()
           ^^^^^^^^^^^^^^^^^^^^^^^^^^^^^
  File "/home/ubuntu/Stackly_AI/venv/lib/python3.12/site-packages/django/views/debug.py", line 428, in get_traceback_html
    c = Context(self.get_traceback_data(), use_l10n=False)
                ^^^^^^^^^^^^^^^^^^^^^^^^^
  File "/home/ubuntu/Stackly_AI/venv/lib/python3.12/site-packages/django/views/debug.py", line 397, in get_traceback_data
    "settings": self.filter.get_safe_settings(),
                ^^^^^^^^^^^^^^^^^^^^^^^^^^^^^^^
  File "/home/ubuntu/Stackly_AI/venv/lib/python3.12/site-packages/django/views/debug.py", line 156, in get_safe_settings
    settings_dict[k] = self.cleanse_setting(k, getattr(settings, k))
                                               ^^^^^^^^^^^^^^^^^^^^
  File "/home/ubuntu/Stackly_AI/venv/lib/python3.12/site-packages/django/conf/__init__.py", line 90, in __getattr__
    raise ImproperlyConfigured("The SECRET_KEY setting must not be empty.")
django.core.exceptions.ImproperlyConfigured: The SECRET_KEY setting must not be empty.

During handling of the above exception, another exception occurred:

Traceback (most recent call last):
  File "/home/ubuntu/Stackly_AI/venv/lib/python3.12/site-packages/django/core/handlers/exception.py", line 55, in inner
    response = get_response(request)
               ^^^^^^^^^^^^^^^^^^^^^
  File "/home/ubuntu/Stackly_AI/venv/lib/python3.12/site-packages/django/utils/deprecation.py", line 120, in __call__
    response = response or self.get_response(request)
                           ^^^^^^^^^^^^^^^^^^^^^^^^^^
  File "/home/ubuntu/Stackly_AI/venv/lib/python3.12/site-packages/django/core/handlers/exception.py", line 57, in inner
    response = response_for_exception(request, exc)
               ^^^^^^^^^^^^^^^^^^^^^^^^^^^^^^^^^^^^
  File "/home/ubuntu/Stackly_AI/venv/lib/python3.12/site-packages/django/core/handlers/exception.py", line 141, in response_for_exception
    response = handle_uncaught_exception(
               ^^^^^^^^^^^^^^^^^^^^^^^^^^
  File "/home/ubuntu/Stackly_AI/venv/lib/python3.12/site-packages/django/core/handlers/exception.py", line 182, in handle_uncaught_exception
    return debug.technical_500_response(request, *exc_info)
           ^^^^^^^^^^^^^^^^^^^^^^^^^^^^^^^^^^^^^^^^^^^^^^^^
  File "/home/ubuntu/Stackly_AI/venv/lib/python3.12/site-packages/django/views/debug.py", line 69, in technical_500_response
    html = reporter.get_traceback_html()
           ^^^^^^^^^^^^^^^^^^^^^^^^^^^^^
  File "/home/ubuntu/Stackly_AI/venv/lib/python3.12/site-packages/django/views/debug.py", line 428, in get_traceback_html
    c = Context(self.get_traceback_data(), use_l10n=False)
                ^^^^^^^^^^^^^^^^^^^^^^^^^
  File "/home/ubuntu/Stackly_AI/venv/lib/python3.12/site-packages/django/views/debug.py", line 397, in get_traceback_data
    "settings": self.filter.get_safe_settings(),
                ^^^^^^^^^^^^^^^^^^^^^^^^^^^^^^^
  File "/home/ubuntu/Stackly_AI/venv/lib/python3.12/site-packages/django/views/debug.py", line 156, in get_safe_settings
    settings_dict[k] = self.cleanse_setting(k, getattr(settings, k))
                                               ^^^^^^^^^^^^^^^^^^^^
  File "/home/ubuntu/Stackly_AI/venv/lib/python3.12/site-packages/django/conf/__init__.py", line 90, in __getattr__
    raise ImproperlyConfigured("The SECRET_KEY setting must not be empty.")
django.core.exceptions.ImproperlyConfigured: The SECRET_KEY setting must not be empty.

During handling of the above exception, another exception occurred:

Traceback (most recent call last):
  File "/home/ubuntu/Stackly_AI/venv/lib/python3.12/site-packages/django/core/handlers/exception.py", line 55, in inner
    response = get_response(request)
               ^^^^^^^^^^^^^^^^^^^^^
  File "/home/ubuntu/Stackly_AI/venv/lib/python3.12/site-packages/django/utils/deprecation.py", line 120, in __call__
    response = response or self.get_response(request)
                           ^^^^^^^^^^^^^^^^^^^^^^^^^^
  File "/home/ubuntu/Stackly_AI/venv/lib/python3.12/site-packages/django/core/handlers/exception.py", line 57, in inner
    response = response_for_exception(request, exc)
               ^^^^^^^^^^^^^^^^^^^^^^^^^^^^^^^^^^^^
  File "/home/ubuntu/Stackly_AI/venv/lib/python3.12/site-packages/django/core/handlers/exception.py", line 141, in response_for_exception
    response = handle_uncaught_exception(
               ^^^^^^^^^^^^^^^^^^^^^^^^^^
  File "/home/ubuntu/Stackly_AI/venv/lib/python3.12/site-packages/django/core/handlers/exception.py", line 182, in handle_uncaught_exception
    return debug.technical_500_response(request, *exc_info)
           ^^^^^^^^^^^^^^^^^^^^^^^^^^^^^^^^^^^^^^^^^^^^^^^^
  File "/home/ubuntu/Stackly_AI/venv/lib/python3.12/site-packages/django/views/debug.py", line 69, in technical_500_response
    html = reporter.get_traceback_html()
           ^^^^^^^^^^^^^^^^^^^^^^^^^^^^^
  File "/home/ubuntu/Stackly_AI/venv/lib/python3.12/site-packages/django/views/debug.py", line 428, in get_traceback_html
    c = Context(self.get_traceback_data(), use_l10n=False)
                ^^^^^^^^^^^^^^^^^^^^^^^^^
  File "/home/ubuntu/Stackly_AI/venv/lib/python3.12/site-packages/django/views/debug.py", line 397, in get_traceback_data
    "settings": self.filter.get_safe_settings(),
                ^^^^^^^^^^^^^^^^^^^^^^^^^^^^^^^
  File "/home/ubuntu/Stackly_AI/venv/lib/python3.12/site-packages/django/views/debug.py", line 156, in get_safe_settings
    settings_dict[k] = self.cleanse_setting(k, getattr(settings, k))
                                               ^^^^^^^^^^^^^^^^^^^^
  File "/home/ubuntu/Stackly_AI/venv/lib/python3.12/site-packages/django/conf/__init__.py", line 90, in __getattr__
    raise ImproperlyConfigured("The SECRET_KEY setting must not be empty.")
django.core.exceptions.ImproperlyConfigured: The SECRET_KEY setting must not be empty.

During handling of the above exception, another exception occurred:

Traceback (most recent call last):
  File "/home/ubuntu/Stackly_AI/venv/lib/python3.12/site-packages/gunicorn/workers/sync.py", line 135, in handle
    self.handle_request(listener, req, client, addr)
  File "/home/ubuntu/Stackly_AI/venv/lib/python3.12/site-packages/gunicorn/workers/sync.py", line 178, in handle_request
    respiter = self.wsgi(environ, resp.start_response)
               ^^^^^^^^^^^^^^^^^^^^^^^^^^^^^^^^^^^^^^^
  File "/home/ubuntu/Stackly_AI/venv/lib/python3.12/site-packages/django/core/handlers/wsgi.py", line 124, in __call__
    response = self.get_response(request)
               ^^^^^^^^^^^^^^^^^^^^^^^^^^
  File "/home/ubuntu/Stackly_AI/venv/lib/python3.12/site-packages/django/core/handlers/base.py", line 140, in get_response
    response = self._middleware_chain(request)
               ^^^^^^^^^^^^^^^^^^^^^^^^^^^^^^^
  File "/home/ubuntu/Stackly_AI/venv/lib/python3.12/site-packages/django/core/handlers/exception.py", line 57, in inner
    response = response_for_exception(request, exc)
               ^^^^^^^^^^^^^^^^^^^^^^^^^^^^^^^^^^^^
  File "/home/ubuntu/Stackly_AI/venv/lib/python3.12/site-packages/django/core/handlers/exception.py", line 141, in response_for_exception
    response = handle_uncaught_exception(
               ^^^^^^^^^^^^^^^^^^^^^^^^^^
  File "/home/ubuntu/Stackly_AI/venv/lib/python3.12/site-packages/django/core/handlers/exception.py", line 182, in handle_uncaught_exception
    return debug.technical_500_response(request, *exc_info)
           ^^^^^^^^^^^^^^^^^^^^^^^^^^^^^^^^^^^^^^^^^^^^^^^^
  File "/home/ubuntu/Stackly_AI/venv/lib/python3.12/site-packages/django/views/debug.py", line 69, in technical_500_response
    html = reporter.get_traceback_html()
           ^^^^^^^^^^^^^^^^^^^^^^^^^^^^^
  File "/home/ubuntu/Stackly_AI/venv/lib/python3.12/site-packages/django/views/debug.py", line 428, in get_traceback_html
    c = Context(self.get_traceback_data(), use_l10n=False)
                ^^^^^^^^^^^^^^^^^^^^^^^^^
  File "/home/ubuntu/Stackly_AI/venv/lib/python3.12/site-packages/django/views/debug.py", line 397, in get_traceback_data
    "settings": self.filter.get_safe_settings(),
                ^^^^^^^^^^^^^^^^^^^^^^^^^^^^^^^
  File "/home/ubuntu/Stackly_AI/venv/lib/python3.12/site-packages/django/views/debug.py", line 156, in get_safe_settings
    settings_dict[k] = self.cleanse_setting(k, getattr(settings, k))
                                               ^^^^^^^^^^^^^^^^^^^^
  File "/home/ubuntu/Stackly_AI/venv/lib/python3.12/site-packages/django/conf/__init__.py", line 90, in __getattr__
    raise ImproperlyConfigured("The SECRET_KEY setting must not be empty.")
django.core.exceptions.ImproperlyConfigured: The SECRET_KEY setting must not be empty.
[2025-10-13 14:08:04 +0000] [9677] [ERROR] Error handling request /favicon.ico
Traceback (most recent call last):
  File "/home/ubuntu/Stackly_AI/venv/lib/python3.12/site-packages/django/core/handlers/exception.py", line 55, in inner
    response = get_response(request)
               ^^^^^^^^^^^^^^^^^^^^^
  File "/home/ubuntu/Stackly_AI/venv/lib/python3.12/site-packages/django/utils/deprecation.py", line 119, in __call__
    response = self.process_request(request)
               ^^^^^^^^^^^^^^^^^^^^^^^^^^^^^
  File "/home/ubuntu/Stackly_AI/venv/lib/python3.12/site-packages/django/contrib/messages/middleware.py", line 12, in process_request
    request._messages = default_storage(request)
                        ^^^^^^^^^^^^^^^^^^^^^^^^
  File "/home/ubuntu/Stackly_AI/venv/lib/python3.12/site-packages/django/contrib/messages/storage/__init__.py", line 12, in default_storage
    return import_string(settings.MESSAGE_STORAGE)(request)
           ^^^^^^^^^^^^^^^^^^^^^^^^^^^^^^^^^^^^^^^^^^^^^^^^
  File "/home/ubuntu/Stackly_AI/venv/lib/python3.12/site-packages/django/contrib/messages/storage/fallback.py", line 17, in __init__
    storage_class(*args, **kwargs) for storage_class in self.storage_classes
    ^^^^^^^^^^^^^^^^^^^^^^^^^^^^^^
  File "/home/ubuntu/Stackly_AI/venv/lib/python3.12/site-packages/django/contrib/messages/storage/cookie.py", line 92, in __init__
    self.signer = signing.get_cookie_signer(salt=self.key_salt)
                  ^^^^^^^^^^^^^^^^^^^^^^^^^^^^^^^^^^^^^^^^^^^^^
  File "/home/ubuntu/Stackly_AI/venv/lib/python3.12/site-packages/django/core/signing.py", line 112, in get_cookie_signer
    key=_cookie_signer_key(settings.SECRET_KEY),
                           ^^^^^^^^^^^^^^^^^^^
  File "/home/ubuntu/Stackly_AI/venv/lib/python3.12/site-packages/django/conf/__init__.py", line 90, in __getattr__
    raise ImproperlyConfigured("The SECRET_KEY setting must not be empty.")
django.core.exceptions.ImproperlyConfigured: The SECRET_KEY setting must not be empty.

During handling of the above exception, another exception occurred:

Traceback (most recent call last):
  File "/home/ubuntu/Stackly_AI/venv/lib/python3.12/site-packages/django/core/handlers/exception.py", line 55, in inner
    response = get_response(request)
               ^^^^^^^^^^^^^^^^^^^^^
  File "/home/ubuntu/Stackly_AI/venv/lib/python3.12/site-packages/django/utils/deprecation.py", line 120, in __call__
    response = response or self.get_response(request)
                           ^^^^^^^^^^^^^^^^^^^^^^^^^^
  File "/home/ubuntu/Stackly_AI/venv/lib/python3.12/site-packages/django/core/handlers/exception.py", line 57, in inner
    response = response_for_exception(request, exc)
               ^^^^^^^^^^^^^^^^^^^^^^^^^^^^^^^^^^^^
  File "/home/ubuntu/Stackly_AI/venv/lib/python3.12/site-packages/django/core/handlers/exception.py", line 141, in response_for_exception
    response = handle_uncaught_exception(
               ^^^^^^^^^^^^^^^^^^^^^^^^^^
  File "/home/ubuntu/Stackly_AI/venv/lib/python3.12/site-packages/django/core/handlers/exception.py", line 182, in handle_uncaught_exception
    return debug.technical_500_response(request, *exc_info)
           ^^^^^^^^^^^^^^^^^^^^^^^^^^^^^^^^^^^^^^^^^^^^^^^^
  File "/home/ubuntu/Stackly_AI/venv/lib/python3.12/site-packages/django/views/debug.py", line 69, in technical_500_response
    html = reporter.get_traceback_html()
           ^^^^^^^^^^^^^^^^^^^^^^^^^^^^^
  File "/home/ubuntu/Stackly_AI/venv/lib/python3.12/site-packages/django/views/debug.py", line 428, in get_traceback_html
    c = Context(self.get_traceback_data(), use_l10n=False)
                ^^^^^^^^^^^^^^^^^^^^^^^^^
  File "/home/ubuntu/Stackly_AI/venv/lib/python3.12/site-packages/django/views/debug.py", line 397, in get_traceback_data
    "settings": self.filter.get_safe_settings(),
                ^^^^^^^^^^^^^^^^^^^^^^^^^^^^^^^
  File "/home/ubuntu/Stackly_AI/venv/lib/python3.12/site-packages/django/views/debug.py", line 156, in get_safe_settings
    settings_dict[k] = self.cleanse_setting(k, getattr(settings, k))
                                               ^^^^^^^^^^^^^^^^^^^^
  File "/home/ubuntu/Stackly_AI/venv/lib/python3.12/site-packages/django/conf/__init__.py", line 90, in __getattr__
    raise ImproperlyConfigured("The SECRET_KEY setting must not be empty.")
django.core.exceptions.ImproperlyConfigured: The SECRET_KEY setting must not be empty.

During handling of the above exception, another exception occurred:

Traceback (most recent call last):
  File "/home/ubuntu/Stackly_AI/venv/lib/python3.12/site-packages/django/core/handlers/exception.py", line 55, in inner
    response = get_response(request)
               ^^^^^^^^^^^^^^^^^^^^^
  File "/home/ubuntu/Stackly_AI/venv/lib/python3.12/site-packages/django/utils/deprecation.py", line 120, in __call__
    response = response or self.get_response(request)
                           ^^^^^^^^^^^^^^^^^^^^^^^^^^
  File "/home/ubuntu/Stackly_AI/venv/lib/python3.12/site-packages/django/core/handlers/exception.py", line 57, in inner
    response = response_for_exception(request, exc)
               ^^^^^^^^^^^^^^^^^^^^^^^^^^^^^^^^^^^^
  File "/home/ubuntu/Stackly_AI/venv/lib/python3.12/site-packages/django/core/handlers/exception.py", line 141, in response_for_exception
    response = handle_uncaught_exception(
               ^^^^^^^^^^^^^^^^^^^^^^^^^^
  File "/home/ubuntu/Stackly_AI/venv/lib/python3.12/site-packages/django/core/handlers/exception.py", line 182, in handle_uncaught_exception
    return debug.technical_500_response(request, *exc_info)
           ^^^^^^^^^^^^^^^^^^^^^^^^^^^^^^^^^^^^^^^^^^^^^^^^
  File "/home/ubuntu/Stackly_AI/venv/lib/python3.12/site-packages/django/views/debug.py", line 69, in technical_500_response
    html = reporter.get_traceback_html()
           ^^^^^^^^^^^^^^^^^^^^^^^^^^^^^
  File "/home/ubuntu/Stackly_AI/venv/lib/python3.12/site-packages/django/views/debug.py", line 428, in get_traceback_html
    c = Context(self.get_traceback_data(), use_l10n=False)
                ^^^^^^^^^^^^^^^^^^^^^^^^^
  File "/home/ubuntu/Stackly_AI/venv/lib/python3.12/site-packages/django/views/debug.py", line 397, in get_traceback_data
    "settings": self.filter.get_safe_settings(),
                ^^^^^^^^^^^^^^^^^^^^^^^^^^^^^^^
  File "/home/ubuntu/Stackly_AI/venv/lib/python3.12/site-packages/django/views/debug.py", line 156, in get_safe_settings
    settings_dict[k] = self.cleanse_setting(k, getattr(settings, k))
                                               ^^^^^^^^^^^^^^^^^^^^
  File "/home/ubuntu/Stackly_AI/venv/lib/python3.12/site-packages/django/conf/__init__.py", line 90, in __getattr__
    raise ImproperlyConfigured("The SECRET_KEY setting must not be empty.")
django.core.exceptions.ImproperlyConfigured: The SECRET_KEY setting must not be empty.

During handling of the above exception, another exception occurred:

Traceback (most recent call last):
  File "/home/ubuntu/Stackly_AI/venv/lib/python3.12/site-packages/django/core/handlers/exception.py", line 55, in inner
    response = get_response(request)
               ^^^^^^^^^^^^^^^^^^^^^
  File "/home/ubuntu/Stackly_AI/venv/lib/python3.12/site-packages/django/utils/deprecation.py", line 120, in __call__
    response = response or self.get_response(request)
                           ^^^^^^^^^^^^^^^^^^^^^^^^^^
  File "/home/ubuntu/Stackly_AI/venv/lib/python3.12/site-packages/django/core/handlers/exception.py", line 57, in inner
    response = response_for_exception(request, exc)
               ^^^^^^^^^^^^^^^^^^^^^^^^^^^^^^^^^^^^
  File "/home/ubuntu/Stackly_AI/venv/lib/python3.12/site-packages/django/core/handlers/exception.py", line 141, in response_for_exception
    response = handle_uncaught_exception(
               ^^^^^^^^^^^^^^^^^^^^^^^^^^
  File "/home/ubuntu/Stackly_AI/venv/lib/python3.12/site-packages/django/core/handlers/exception.py", line 182, in handle_uncaught_exception
    return debug.technical_500_response(request, *exc_info)
           ^^^^^^^^^^^^^^^^^^^^^^^^^^^^^^^^^^^^^^^^^^^^^^^^
  File "/home/ubuntu/Stackly_AI/venv/lib/python3.12/site-packages/django/views/debug.py", line 69, in technical_500_response
    html = reporter.get_traceback_html()
           ^^^^^^^^^^^^^^^^^^^^^^^^^^^^^
  File "/home/ubuntu/Stackly_AI/venv/lib/python3.12/site-packages/django/views/debug.py", line 428, in get_traceback_html
    c = Context(self.get_traceback_data(), use_l10n=False)
                ^^^^^^^^^^^^^^^^^^^^^^^^^
  File "/home/ubuntu/Stackly_AI/venv/lib/python3.12/site-packages/django/views/debug.py", line 397, in get_traceback_data
    "settings": self.filter.get_safe_settings(),
                ^^^^^^^^^^^^^^^^^^^^^^^^^^^^^^^
  File "/home/ubuntu/Stackly_AI/venv/lib/python3.12/site-packages/django/views/debug.py", line 156, in get_safe_settings
    settings_dict[k] = self.cleanse_setting(k, getattr(settings, k))
                                               ^^^^^^^^^^^^^^^^^^^^
  File "/home/ubuntu/Stackly_AI/venv/lib/python3.12/site-packages/django/conf/__init__.py", line 90, in __getattr__
    raise ImproperlyConfigured("The SECRET_KEY setting must not be empty.")
django.core.exceptions.ImproperlyConfigured: The SECRET_KEY setting must not be empty.

During handling of the above exception, another exception occurred:

Traceback (most recent call last):
  File "/home/ubuntu/Stackly_AI/venv/lib/python3.12/site-packages/django/core/handlers/exception.py", line 55, in inner
    response = get_response(request)
               ^^^^^^^^^^^^^^^^^^^^^
  File "/home/ubuntu/Stackly_AI/venv/lib/python3.12/site-packages/django/utils/deprecation.py", line 120, in __call__
    response = response or self.get_response(request)
                           ^^^^^^^^^^^^^^^^^^^^^^^^^^
  File "/home/ubuntu/Stackly_AI/venv/lib/python3.12/site-packages/django/core/handlers/exception.py", line 57, in inner
    response = response_for_exception(request, exc)
               ^^^^^^^^^^^^^^^^^^^^^^^^^^^^^^^^^^^^
  File "/home/ubuntu/Stackly_AI/venv/lib/python3.12/site-packages/django/core/handlers/exception.py", line 141, in response_for_exception
    response = handle_uncaught_exception(
               ^^^^^^^^^^^^^^^^^^^^^^^^^^
  File "/home/ubuntu/Stackly_AI/venv/lib/python3.12/site-packages/django/core/handlers/exception.py", line 182, in handle_uncaught_exception
    return debug.technical_500_response(request, *exc_info)
           ^^^^^^^^^^^^^^^^^^^^^^^^^^^^^^^^^^^^^^^^^^^^^^^^
  File "/home/ubuntu/Stackly_AI/venv/lib/python3.12/site-packages/django/views/debug.py", line 69, in technical_500_response
    html = reporter.get_traceback_html()
           ^^^^^^^^^^^^^^^^^^^^^^^^^^^^^
  File "/home/ubuntu/Stackly_AI/venv/lib/python3.12/site-packages/django/views/debug.py", line 428, in get_traceback_html
    c = Context(self.get_traceback_data(), use_l10n=False)
                ^^^^^^^^^^^^^^^^^^^^^^^^^
  File "/home/ubuntu/Stackly_AI/venv/lib/python3.12/site-packages/django/views/debug.py", line 397, in get_traceback_data
    "settings": self.filter.get_safe_settings(),
                ^^^^^^^^^^^^^^^^^^^^^^^^^^^^^^^
  File "/home/ubuntu/Stackly_AI/venv/lib/python3.12/site-packages/django/views/debug.py", line 156, in get_safe_settings
    settings_dict[k] = self.cleanse_setting(k, getattr(settings, k))
                                               ^^^^^^^^^^^^^^^^^^^^
  File "/home/ubuntu/Stackly_AI/venv/lib/python3.12/site-packages/django/conf/__init__.py", line 90, in __getattr__
    raise ImproperlyConfigured("The SECRET_KEY setting must not be empty.")
django.core.exceptions.ImproperlyConfigured: The SECRET_KEY setting must not be empty.

During handling of the above exception, another exception occurred:

Traceback (most recent call last):
  File "/home/ubuntu/Stackly_AI/venv/lib/python3.12/site-packages/django/core/handlers/exception.py", line 55, in inner
    response = get_response(request)
               ^^^^^^^^^^^^^^^^^^^^^
  File "/home/ubuntu/Stackly_AI/venv/lib/python3.12/site-packages/django/utils/deprecation.py", line 120, in __call__
    response = response or self.get_response(request)
                           ^^^^^^^^^^^^^^^^^^^^^^^^^^
  File "/home/ubuntu/Stackly_AI/venv/lib/python3.12/site-packages/django/core/handlers/exception.py", line 57, in inner
    response = response_for_exception(request, exc)
               ^^^^^^^^^^^^^^^^^^^^^^^^^^^^^^^^^^^^
  File "/home/ubuntu/Stackly_AI/venv/lib/python3.12/site-packages/django/core/handlers/exception.py", line 141, in response_for_exception
    response = handle_uncaught_exception(
               ^^^^^^^^^^^^^^^^^^^^^^^^^^
  File "/home/ubuntu/Stackly_AI/venv/lib/python3.12/site-packages/django/core/handlers/exception.py", line 182, in handle_uncaught_exception
    return debug.technical_500_response(request, *exc_info)
           ^^^^^^^^^^^^^^^^^^^^^^^^^^^^^^^^^^^^^^^^^^^^^^^^
  File "/home/ubuntu/Stackly_AI/venv/lib/python3.12/site-packages/django/views/debug.py", line 69, in technical_500_response
    html = reporter.get_traceback_html()
           ^^^^^^^^^^^^^^^^^^^^^^^^^^^^^
  File "/home/ubuntu/Stackly_AI/venv/lib/python3.12/site-packages/django/views/debug.py", line 428, in get_traceback_html
    c = Context(self.get_traceback_data(), use_l10n=False)
                ^^^^^^^^^^^^^^^^^^^^^^^^^
  File "/home/ubuntu/Stackly_AI/venv/lib/python3.12/site-packages/django/views/debug.py", line 397, in get_traceback_data
    "settings": self.filter.get_safe_settings(),
                ^^^^^^^^^^^^^^^^^^^^^^^^^^^^^^^
  File "/home/ubuntu/Stackly_AI/venv/lib/python3.12/site-packages/django/views/debug.py", line 156, in get_safe_settings
    settings_dict[k] = self.cleanse_setting(k, getattr(settings, k))
                                               ^^^^^^^^^^^^^^^^^^^^
  File "/home/ubuntu/Stackly_AI/venv/lib/python3.12/site-packages/django/conf/__init__.py", line 90, in __getattr__
    raise ImproperlyConfigured("The SECRET_KEY setting must not be empty.")
django.core.exceptions.ImproperlyConfigured: The SECRET_KEY setting must not be empty.

During handling of the above exception, another exception occurred:

Traceback (most recent call last):
  File "/home/ubuntu/Stackly_AI/venv/lib/python3.12/site-packages/gunicorn/workers/sync.py", line 135, in handle
    self.handle_request(listener, req, client, addr)
  File "/home/ubuntu/Stackly_AI/venv/lib/python3.12/site-packages/gunicorn/workers/sync.py", line 178, in handle_request
    respiter = self.wsgi(environ, resp.start_response)
               ^^^^^^^^^^^^^^^^^^^^^^^^^^^^^^^^^^^^^^^
  File "/home/ubuntu/Stackly_AI/venv/lib/python3.12/site-packages/django/core/handlers/wsgi.py", line 124, in __call__
    response = self.get_response(request)
               ^^^^^^^^^^^^^^^^^^^^^^^^^^
  File "/home/ubuntu/Stackly_AI/venv/lib/python3.12/site-packages/django/core/handlers/base.py", line 140, in get_response
    response = self._middleware_chain(request)
               ^^^^^^^^^^^^^^^^^^^^^^^^^^^^^^^
  File "/home/ubuntu/Stackly_AI/venv/lib/python3.12/site-packages/django/core/handlers/exception.py", line 57, in inner
    response = response_for_exception(request, exc)
               ^^^^^^^^^^^^^^^^^^^^^^^^^^^^^^^^^^^^
  File "/home/ubuntu/Stackly_AI/venv/lib/python3.12/site-packages/django/core/handlers/exception.py", line 141, in response_for_exception
    response = handle_uncaught_exception(
               ^^^^^^^^^^^^^^^^^^^^^^^^^^
  File "/home/ubuntu/Stackly_AI/venv/lib/python3.12/site-packages/django/core/handlers/exception.py", line 182, in handle_uncaught_exception
    return debug.technical_500_response(request, *exc_info)
           ^^^^^^^^^^^^^^^^^^^^^^^^^^^^^^^^^^^^^^^^^^^^^^^^
  File "/home/ubuntu/Stackly_AI/venv/lib/python3.12/site-packages/django/views/debug.py", line 69, in technical_500_response
    html = reporter.get_traceback_html()
           ^^^^^^^^^^^^^^^^^^^^^^^^^^^^^
  File "/home/ubuntu/Stackly_AI/venv/lib/python3.12/site-packages/django/views/debug.py", line 428, in get_traceback_html
    c = Context(self.get_traceback_data(), use_l10n=False)
                ^^^^^^^^^^^^^^^^^^^^^^^^^
  File "/home/ubuntu/Stackly_AI/venv/lib/python3.12/site-packages/django/views/debug.py", line 397, in get_traceback_data
    "settings": self.filter.get_safe_settings(),
                ^^^^^^^^^^^^^^^^^^^^^^^^^^^^^^^
  File "/home/ubuntu/Stackly_AI/venv/lib/python3.12/site-packages/django/views/debug.py", line 156, in get_safe_settings
    settings_dict[k] = self.cleanse_setting(k, getattr(settings, k))
                                               ^^^^^^^^^^^^^^^^^^^^
  File "/home/ubuntu/Stackly_AI/venv/lib/python3.12/site-packages/django/conf/__init__.py", line 90, in __getattr__
    raise ImproperlyConfigured("The SECRET_KEY setting must not be empty.")
django.core.exceptions.ImproperlyConfigured: The SECRET_KEY setting must not be empty.
[2025-10-13 14:08:20 +0000] [9676] [INFO] Handling signal: term
[2025-10-13 14:08:20 +0000] [9677] [INFO] Worker exiting (pid: 9677)
[2025-10-13 14:08:20 +0000] [9678] [INFO] Worker exiting (pid: 9678)
[2025-10-13 14:08:20 +0000] [9679] [INFO] Worker exiting (pid: 9679)
[2025-10-13 14:08:20 +0000] [9846] [INFO] Starting gunicorn 21.2.0
[2025-10-13 14:08:20 +0000] [9846] [INFO] Listening at: http://0.0.0.0:8001 (9846)
[2025-10-13 14:08:20 +0000] [9846] [INFO] Using worker: sync
[2025-10-13 14:08:20 +0000] [9847] [INFO] Booting worker with pid: 9847
[2025-10-13 14:08:20 +0000] [9676] [INFO] Shutting down: Master
[2025-10-13 14:08:20 +0000] [9848] [INFO] Booting worker with pid: 9848
[2025-10-13 14:08:21 +0000] [9849] [INFO] Booting worker with pid: 9849
[2025-10-13 14:09:55 +0000] [9847] [ERROR] Error handling request /
Traceback (most recent call last):
  File "/home/ubuntu/Stackly_AI/venv/lib/python3.12/site-packages/django/core/handlers/exception.py", line 55, in inner
    response = get_response(request)
               ^^^^^^^^^^^^^^^^^^^^^
  File "/home/ubuntu/Stackly_AI/venv/lib/python3.12/site-packages/django/utils/deprecation.py", line 119, in __call__
    response = self.process_request(request)
               ^^^^^^^^^^^^^^^^^^^^^^^^^^^^^
  File "/home/ubuntu/Stackly_AI/venv/lib/python3.12/site-packages/django/contrib/messages/middleware.py", line 12, in process_request
    request._messages = default_storage(request)
                        ^^^^^^^^^^^^^^^^^^^^^^^^
  File "/home/ubuntu/Stackly_AI/venv/lib/python3.12/site-packages/django/contrib/messages/storage/__init__.py", line 12, in default_storage
    return import_string(settings.MESSAGE_STORAGE)(request)
           ^^^^^^^^^^^^^^^^^^^^^^^^^^^^^^^^^^^^^^^^^^^^^^^^
  File "/home/ubuntu/Stackly_AI/venv/lib/python3.12/site-packages/django/contrib/messages/storage/fallback.py", line 17, in __init__
    storage_class(*args, **kwargs) for storage_class in self.storage_classes
    ^^^^^^^^^^^^^^^^^^^^^^^^^^^^^^
  File "/home/ubuntu/Stackly_AI/venv/lib/python3.12/site-packages/django/contrib/messages/storage/cookie.py", line 92, in __init__
    self.signer = signing.get_cookie_signer(salt=self.key_salt)
                  ^^^^^^^^^^^^^^^^^^^^^^^^^^^^^^^^^^^^^^^^^^^^^
  File "/home/ubuntu/Stackly_AI/venv/lib/python3.12/site-packages/django/core/signing.py", line 112, in get_cookie_signer
    key=_cookie_signer_key(settings.SECRET_KEY),
                           ^^^^^^^^^^^^^^^^^^^
  File "/home/ubuntu/Stackly_AI/venv/lib/python3.12/site-packages/django/conf/__init__.py", line 90, in __getattr__
    raise ImproperlyConfigured("The SECRET_KEY setting must not be empty.")
django.core.exceptions.ImproperlyConfigured: The SECRET_KEY setting must not be empty.

During handling of the above exception, another exception occurred:

Traceback (most recent call last):
  File "/home/ubuntu/Stackly_AI/venv/lib/python3.12/site-packages/django/core/handlers/exception.py", line 55, in inner
    response = get_response(request)
               ^^^^^^^^^^^^^^^^^^^^^
  File "/home/ubuntu/Stackly_AI/venv/lib/python3.12/site-packages/django/utils/deprecation.py", line 120, in __call__
    response = response or self.get_response(request)
                           ^^^^^^^^^^^^^^^^^^^^^^^^^^
  File "/home/ubuntu/Stackly_AI/venv/lib/python3.12/site-packages/django/core/handlers/exception.py", line 57, in inner
    response = response_for_exception(request, exc)
               ^^^^^^^^^^^^^^^^^^^^^^^^^^^^^^^^^^^^
  File "/home/ubuntu/Stackly_AI/venv/lib/python3.12/site-packages/django/core/handlers/exception.py", line 141, in response_for_exception
    response = handle_uncaught_exception(
               ^^^^^^^^^^^^^^^^^^^^^^^^^^
  File "/home/ubuntu/Stackly_AI/venv/lib/python3.12/site-packages/django/core/handlers/exception.py", line 182, in handle_uncaught_exception
    return debug.technical_500_response(request, *exc_info)
           ^^^^^^^^^^^^^^^^^^^^^^^^^^^^^^^^^^^^^^^^^^^^^^^^
  File "/home/ubuntu/Stackly_AI/venv/lib/python3.12/site-packages/django/views/debug.py", line 69, in technical_500_response
    html = reporter.get_traceback_html()
           ^^^^^^^^^^^^^^^^^^^^^^^^^^^^^
  File "/home/ubuntu/Stackly_AI/venv/lib/python3.12/site-packages/django/views/debug.py", line 428, in get_traceback_html
    c = Context(self.get_traceback_data(), use_l10n=False)
                ^^^^^^^^^^^^^^^^^^^^^^^^^
  File "/home/ubuntu/Stackly_AI/venv/lib/python3.12/site-packages/django/views/debug.py", line 397, in get_traceback_data
    "settings": self.filter.get_safe_settings(),
                ^^^^^^^^^^^^^^^^^^^^^^^^^^^^^^^
  File "/home/ubuntu/Stackly_AI/venv/lib/python3.12/site-packages/django/views/debug.py", line 156, in get_safe_settings
    settings_dict[k] = self.cleanse_setting(k, getattr(settings, k))
                                               ^^^^^^^^^^^^^^^^^^^^
  File "/home/ubuntu/Stackly_AI/venv/lib/python3.12/site-packages/django/conf/__init__.py", line 90, in __getattr__
    raise ImproperlyConfigured("The SECRET_KEY setting must not be empty.")
django.core.exceptions.ImproperlyConfigured: The SECRET_KEY setting must not be empty.

During handling of the above exception, another exception occurred:

Traceback (most recent call last):
  File "/home/ubuntu/Stackly_AI/venv/lib/python3.12/site-packages/django/core/handlers/exception.py", line 55, in inner
    response = get_response(request)
               ^^^^^^^^^^^^^^^^^^^^^
  File "/home/ubuntu/Stackly_AI/venv/lib/python3.12/site-packages/django/utils/deprecation.py", line 120, in __call__
    response = response or self.get_response(request)
                           ^^^^^^^^^^^^^^^^^^^^^^^^^^
  File "/home/ubuntu/Stackly_AI/venv/lib/python3.12/site-packages/django/core/handlers/exception.py", line 57, in inner
    response = response_for_exception(request, exc)
               ^^^^^^^^^^^^^^^^^^^^^^^^^^^^^^^^^^^^
  File "/home/ubuntu/Stackly_AI/venv/lib/python3.12/site-packages/django/core/handlers/exception.py", line 141, in response_for_exception
    response = handle_uncaught_exception(
               ^^^^^^^^^^^^^^^^^^^^^^^^^^
  File "/home/ubuntu/Stackly_AI/venv/lib/python3.12/site-packages/django/core/handlers/exception.py", line 182, in handle_uncaught_exception
    return debug.technical_500_response(request, *exc_info)
           ^^^^^^^^^^^^^^^^^^^^^^^^^^^^^^^^^^^^^^^^^^^^^^^^
  File "/home/ubuntu/Stackly_AI/venv/lib/python3.12/site-packages/django/views/debug.py", line 69, in technical_500_response
    html = reporter.get_traceback_html()
           ^^^^^^^^^^^^^^^^^^^^^^^^^^^^^
  File "/home/ubuntu/Stackly_AI/venv/lib/python3.12/site-packages/django/views/debug.py", line 428, in get_traceback_html
    c = Context(self.get_traceback_data(), use_l10n=False)
                ^^^^^^^^^^^^^^^^^^^^^^^^^
  File "/home/ubuntu/Stackly_AI/venv/lib/python3.12/site-packages/django/views/debug.py", line 397, in get_traceback_data
    "settings": self.filter.get_safe_settings(),
                ^^^^^^^^^^^^^^^^^^^^^^^^^^^^^^^
  File "/home/ubuntu/Stackly_AI/venv/lib/python3.12/site-packages/django/views/debug.py", line 156, in get_safe_settings
    settings_dict[k] = self.cleanse_setting(k, getattr(settings, k))
                                               ^^^^^^^^^^^^^^^^^^^^
  File "/home/ubuntu/Stackly_AI/venv/lib/python3.12/site-packages/django/conf/__init__.py", line 90, in __getattr__
    raise ImproperlyConfigured("The SECRET_KEY setting must not be empty.")
django.core.exceptions.ImproperlyConfigured: The SECRET_KEY setting must not be empty.

During handling of the above exception, another exception occurred:

Traceback (most recent call last):
  File "/home/ubuntu/Stackly_AI/venv/lib/python3.12/site-packages/django/core/handlers/exception.py", line 55, in inner
    response = get_response(request)
               ^^^^^^^^^^^^^^^^^^^^^
  File "/home/ubuntu/Stackly_AI/venv/lib/python3.12/site-packages/django/utils/deprecation.py", line 120, in __call__
    response = response or self.get_response(request)
                           ^^^^^^^^^^^^^^^^^^^^^^^^^^
  File "/home/ubuntu/Stackly_AI/venv/lib/python3.12/site-packages/django/core/handlers/exception.py", line 57, in inner
    response = response_for_exception(request, exc)
               ^^^^^^^^^^^^^^^^^^^^^^^^^^^^^^^^^^^^
  File "/home/ubuntu/Stackly_AI/venv/lib/python3.12/site-packages/django/core/handlers/exception.py", line 141, in response_for_exception
    response = handle_uncaught_exception(
               ^^^^^^^^^^^^^^^^^^^^^^^^^^
  File "/home/ubuntu/Stackly_AI/venv/lib/python3.12/site-packages/django/core/handlers/exception.py", line 182, in handle_uncaught_exception
    return debug.technical_500_response(request, *exc_info)
           ^^^^^^^^^^^^^^^^^^^^^^^^^^^^^^^^^^^^^^^^^^^^^^^^
  File "/home/ubuntu/Stackly_AI/venv/lib/python3.12/site-packages/django/views/debug.py", line 69, in technical_500_response
    html = reporter.get_traceback_html()
           ^^^^^^^^^^^^^^^^^^^^^^^^^^^^^
  File "/home/ubuntu/Stackly_AI/venv/lib/python3.12/site-packages/django/views/debug.py", line 428, in get_traceback_html
    c = Context(self.get_traceback_data(), use_l10n=False)
                ^^^^^^^^^^^^^^^^^^^^^^^^^
  File "/home/ubuntu/Stackly_AI/venv/lib/python3.12/site-packages/django/views/debug.py", line 397, in get_traceback_data
    "settings": self.filter.get_safe_settings(),
                ^^^^^^^^^^^^^^^^^^^^^^^^^^^^^^^
  File "/home/ubuntu/Stackly_AI/venv/lib/python3.12/site-packages/django/views/debug.py", line 156, in get_safe_settings
    settings_dict[k] = self.cleanse_setting(k, getattr(settings, k))
                                               ^^^^^^^^^^^^^^^^^^^^
  File "/home/ubuntu/Stackly_AI/venv/lib/python3.12/site-packages/django/conf/__init__.py", line 90, in __getattr__
    raise ImproperlyConfigured("The SECRET_KEY setting must not be empty.")
django.core.exceptions.ImproperlyConfigured: The SECRET_KEY setting must not be empty.

During handling of the above exception, another exception occurred:

Traceback (most recent call last):
  File "/home/ubuntu/Stackly_AI/venv/lib/python3.12/site-packages/django/core/handlers/exception.py", line 55, in inner
    response = get_response(request)
               ^^^^^^^^^^^^^^^^^^^^^
  File "/home/ubuntu/Stackly_AI/venv/lib/python3.12/site-packages/django/utils/deprecation.py", line 120, in __call__
    response = response or self.get_response(request)
                           ^^^^^^^^^^^^^^^^^^^^^^^^^^
  File "/home/ubuntu/Stackly_AI/venv/lib/python3.12/site-packages/django/core/handlers/exception.py", line 57, in inner
    response = response_for_exception(request, exc)
               ^^^^^^^^^^^^^^^^^^^^^^^^^^^^^^^^^^^^
  File "/home/ubuntu/Stackly_AI/venv/lib/python3.12/site-packages/django/core/handlers/exception.py", line 141, in response_for_exception
    response = handle_uncaught_exception(
               ^^^^^^^^^^^^^^^^^^^^^^^^^^
  File "/home/ubuntu/Stackly_AI/venv/lib/python3.12/site-packages/django/core/handlers/exception.py", line 182, in handle_uncaught_exception
    return debug.technical_500_response(request, *exc_info)
           ^^^^^^^^^^^^^^^^^^^^^^^^^^^^^^^^^^^^^^^^^^^^^^^^
  File "/home/ubuntu/Stackly_AI/venv/lib/python3.12/site-packages/django/views/debug.py", line 69, in technical_500_response
    html = reporter.get_traceback_html()
           ^^^^^^^^^^^^^^^^^^^^^^^^^^^^^
  File "/home/ubuntu/Stackly_AI/venv/lib/python3.12/site-packages/django/views/debug.py", line 428, in get_traceback_html
    c = Context(self.get_traceback_data(), use_l10n=False)
                ^^^^^^^^^^^^^^^^^^^^^^^^^
  File "/home/ubuntu/Stackly_AI/venv/lib/python3.12/site-packages/django/views/debug.py", line 397, in get_traceback_data
    "settings": self.filter.get_safe_settings(),
                ^^^^^^^^^^^^^^^^^^^^^^^^^^^^^^^
  File "/home/ubuntu/Stackly_AI/venv/lib/python3.12/site-packages/django/views/debug.py", line 156, in get_safe_settings
    settings_dict[k] = self.cleanse_setting(k, getattr(settings, k))
                                               ^^^^^^^^^^^^^^^^^^^^
  File "/home/ubuntu/Stackly_AI/venv/lib/python3.12/site-packages/django/conf/__init__.py", line 90, in __getattr__
    raise ImproperlyConfigured("The SECRET_KEY setting must not be empty.")
django.core.exceptions.ImproperlyConfigured: The SECRET_KEY setting must not be empty.

During handling of the above exception, another exception occurred:

Traceback (most recent call last):
  File "/home/ubuntu/Stackly_AI/venv/lib/python3.12/site-packages/django/core/handlers/exception.py", line 55, in inner
    response = get_response(request)
               ^^^^^^^^^^^^^^^^^^^^^
  File "/home/ubuntu/Stackly_AI/venv/lib/python3.12/site-packages/django/utils/deprecation.py", line 120, in __call__
    response = response or self.get_response(request)
                           ^^^^^^^^^^^^^^^^^^^^^^^^^^
  File "/home/ubuntu/Stackly_AI/venv/lib/python3.12/site-packages/django/core/handlers/exception.py", line 57, in inner
    response = response_for_exception(request, exc)
               ^^^^^^^^^^^^^^^^^^^^^^^^^^^^^^^^^^^^
  File "/home/ubuntu/Stackly_AI/venv/lib/python3.12/site-packages/django/core/handlers/exception.py", line 141, in response_for_exception
    response = handle_uncaught_exception(
               ^^^^^^^^^^^^^^^^^^^^^^^^^^
  File "/home/ubuntu/Stackly_AI/venv/lib/python3.12/site-packages/django/core/handlers/exception.py", line 182, in handle_uncaught_exception
    return debug.technical_500_response(request, *exc_info)
           ^^^^^^^^^^^^^^^^^^^^^^^^^^^^^^^^^^^^^^^^^^^^^^^^
  File "/home/ubuntu/Stackly_AI/venv/lib/python3.12/site-packages/django/views/debug.py", line 69, in technical_500_response
    html = reporter.get_traceback_html()
           ^^^^^^^^^^^^^^^^^^^^^^^^^^^^^
  File "/home/ubuntu/Stackly_AI/venv/lib/python3.12/site-packages/django/views/debug.py", line 428, in get_traceback_html
    c = Context(self.get_traceback_data(), use_l10n=False)
                ^^^^^^^^^^^^^^^^^^^^^^^^^
  File "/home/ubuntu/Stackly_AI/venv/lib/python3.12/site-packages/django/views/debug.py", line 397, in get_traceback_data
    "settings": self.filter.get_safe_settings(),
                ^^^^^^^^^^^^^^^^^^^^^^^^^^^^^^^
  File "/home/ubuntu/Stackly_AI/venv/lib/python3.12/site-packages/django/views/debug.py", line 156, in get_safe_settings
    settings_dict[k] = self.cleanse_setting(k, getattr(settings, k))
                                               ^^^^^^^^^^^^^^^^^^^^
  File "/home/ubuntu/Stackly_AI/venv/lib/python3.12/site-packages/django/conf/__init__.py", line 90, in __getattr__
    raise ImproperlyConfigured("The SECRET_KEY setting must not be empty.")
django.core.exceptions.ImproperlyConfigured: The SECRET_KEY setting must not be empty.

During handling of the above exception, another exception occurred:

Traceback (most recent call last):
  File "/home/ubuntu/Stackly_AI/venv/lib/python3.12/site-packages/gunicorn/workers/sync.py", line 135, in handle
    self.handle_request(listener, req, client, addr)
  File "/home/ubuntu/Stackly_AI/venv/lib/python3.12/site-packages/gunicorn/workers/sync.py", line 178, in handle_request
    respiter = self.wsgi(environ, resp.start_response)
               ^^^^^^^^^^^^^^^^^^^^^^^^^^^^^^^^^^^^^^^
  File "/home/ubuntu/Stackly_AI/venv/lib/python3.12/site-packages/django/core/handlers/wsgi.py", line 124, in __call__
    response = self.get_response(request)
               ^^^^^^^^^^^^^^^^^^^^^^^^^^
  File "/home/ubuntu/Stackly_AI/venv/lib/python3.12/site-packages/django/core/handlers/base.py", line 140, in get_response
    response = self._middleware_chain(request)
               ^^^^^^^^^^^^^^^^^^^^^^^^^^^^^^^
  File "/home/ubuntu/Stackly_AI/venv/lib/python3.12/site-packages/django/core/handlers/exception.py", line 57, in inner
    response = response_for_exception(request, exc)
               ^^^^^^^^^^^^^^^^^^^^^^^^^^^^^^^^^^^^
  File "/home/ubuntu/Stackly_AI/venv/lib/python3.12/site-packages/django/core/handlers/exception.py", line 141, in response_for_exception
    response = handle_uncaught_exception(
               ^^^^^^^^^^^^^^^^^^^^^^^^^^
  File "/home/ubuntu/Stackly_AI/venv/lib/python3.12/site-packages/django/core/handlers/exception.py", line 182, in handle_uncaught_exception
    return debug.technical_500_response(request, *exc_info)
           ^^^^^^^^^^^^^^^^^^^^^^^^^^^^^^^^^^^^^^^^^^^^^^^^
  File "/home/ubuntu/Stackly_AI/venv/lib/python3.12/site-packages/django/views/debug.py", line 69, in technical_500_response
    html = reporter.get_traceback_html()
           ^^^^^^^^^^^^^^^^^^^^^^^^^^^^^
  File "/home/ubuntu/Stackly_AI/venv/lib/python3.12/site-packages/django/views/debug.py", line 428, in get_traceback_html
    c = Context(self.get_traceback_data(), use_l10n=False)
                ^^^^^^^^^^^^^^^^^^^^^^^^^
  File "/home/ubuntu/Stackly_AI/venv/lib/python3.12/site-packages/django/views/debug.py", line 397, in get_traceback_data
    "settings": self.filter.get_safe_settings(),
                ^^^^^^^^^^^^^^^^^^^^^^^^^^^^^^^
  File "/home/ubuntu/Stackly_AI/venv/lib/python3.12/site-packages/django/views/debug.py", line 156, in get_safe_settings
    settings_dict[k] = self.cleanse_setting(k, getattr(settings, k))
                                               ^^^^^^^^^^^^^^^^^^^^
  File "/home/ubuntu/Stackly_AI/venv/lib/python3.12/site-packages/django/conf/__init__.py", line 90, in __getattr__
    raise ImproperlyConfigured("The SECRET_KEY setting must not be empty.")
django.core.exceptions.ImproperlyConfigured: The SECRET_KEY setting must not be empty.
[2025-10-13 14:09:55 +0000] [9849] [ERROR] Error handling request /favicon.ico
Traceback (most recent call last):
  File "/home/ubuntu/Stackly_AI/venv/lib/python3.12/site-packages/django/core/handlers/exception.py", line 55, in inner
    response = get_response(request)
               ^^^^^^^^^^^^^^^^^^^^^
  File "/home/ubuntu/Stackly_AI/venv/lib/python3.12/site-packages/django/utils/deprecation.py", line 119, in __call__
    response = self.process_request(request)
               ^^^^^^^^^^^^^^^^^^^^^^^^^^^^^
  File "/home/ubuntu/Stackly_AI/venv/lib/python3.12/site-packages/django/contrib/messages/middleware.py", line 12, in process_request
    request._messages = default_storage(request)
                        ^^^^^^^^^^^^^^^^^^^^^^^^
  File "/home/ubuntu/Stackly_AI/venv/lib/python3.12/site-packages/django/contrib/messages/storage/__init__.py", line 12, in default_storage
    return import_string(settings.MESSAGE_STORAGE)(request)
           ^^^^^^^^^^^^^^^^^^^^^^^^^^^^^^^^^^^^^^^^^^^^^^^^
  File "/home/ubuntu/Stackly_AI/venv/lib/python3.12/site-packages/django/contrib/messages/storage/fallback.py", line 17, in __init__
    storage_class(*args, **kwargs) for storage_class in self.storage_classes
    ^^^^^^^^^^^^^^^^^^^^^^^^^^^^^^
  File "/home/ubuntu/Stackly_AI/venv/lib/python3.12/site-packages/django/contrib/messages/storage/cookie.py", line 92, in __init__
    self.signer = signing.get_cookie_signer(salt=self.key_salt)
                  ^^^^^^^^^^^^^^^^^^^^^^^^^^^^^^^^^^^^^^^^^^^^^
  File "/home/ubuntu/Stackly_AI/venv/lib/python3.12/site-packages/django/core/signing.py", line 112, in get_cookie_signer
    key=_cookie_signer_key(settings.SECRET_KEY),
                           ^^^^^^^^^^^^^^^^^^^
  File "/home/ubuntu/Stackly_AI/venv/lib/python3.12/site-packages/django/conf/__init__.py", line 90, in __getattr__
    raise ImproperlyConfigured("The SECRET_KEY setting must not be empty.")
django.core.exceptions.ImproperlyConfigured: The SECRET_KEY setting must not be empty.

During handling of the above exception, another exception occurred:

Traceback (most recent call last):
  File "/home/ubuntu/Stackly_AI/venv/lib/python3.12/site-packages/django/core/handlers/exception.py", line 55, in inner
    response = get_response(request)
               ^^^^^^^^^^^^^^^^^^^^^
  File "/home/ubuntu/Stackly_AI/venv/lib/python3.12/site-packages/django/utils/deprecation.py", line 120, in __call__
    response = response or self.get_response(request)
                           ^^^^^^^^^^^^^^^^^^^^^^^^^^
  File "/home/ubuntu/Stackly_AI/venv/lib/python3.12/site-packages/django/core/handlers/exception.py", line 57, in inner
    response = response_for_exception(request, exc)
               ^^^^^^^^^^^^^^^^^^^^^^^^^^^^^^^^^^^^
  File "/home/ubuntu/Stackly_AI/venv/lib/python3.12/site-packages/django/core/handlers/exception.py", line 141, in response_for_exception
    response = handle_uncaught_exception(
               ^^^^^^^^^^^^^^^^^^^^^^^^^^
  File "/home/ubuntu/Stackly_AI/venv/lib/python3.12/site-packages/django/core/handlers/exception.py", line 182, in handle_uncaught_exception
    return debug.technical_500_response(request, *exc_info)
           ^^^^^^^^^^^^^^^^^^^^^^^^^^^^^^^^^^^^^^^^^^^^^^^^
  File "/home/ubuntu/Stackly_AI/venv/lib/python3.12/site-packages/django/views/debug.py", line 69, in technical_500_response
    html = reporter.get_traceback_html()
           ^^^^^^^^^^^^^^^^^^^^^^^^^^^^^
  File "/home/ubuntu/Stackly_AI/venv/lib/python3.12/site-packages/django/views/debug.py", line 428, in get_traceback_html
    c = Context(self.get_traceback_data(), use_l10n=False)
                ^^^^^^^^^^^^^^^^^^^^^^^^^
  File "/home/ubuntu/Stackly_AI/venv/lib/python3.12/site-packages/django/views/debug.py", line 397, in get_traceback_data
    "settings": self.filter.get_safe_settings(),
                ^^^^^^^^^^^^^^^^^^^^^^^^^^^^^^^
  File "/home/ubuntu/Stackly_AI/venv/lib/python3.12/site-packages/django/views/debug.py", line 156, in get_safe_settings
    settings_dict[k] = self.cleanse_setting(k, getattr(settings, k))
                                               ^^^^^^^^^^^^^^^^^^^^
  File "/home/ubuntu/Stackly_AI/venv/lib/python3.12/site-packages/django/conf/__init__.py", line 90, in __getattr__
    raise ImproperlyConfigured("The SECRET_KEY setting must not be empty.")
django.core.exceptions.ImproperlyConfigured: The SECRET_KEY setting must not be empty.

During handling of the above exception, another exception occurred:

Traceback (most recent call last):
  File "/home/ubuntu/Stackly_AI/venv/lib/python3.12/site-packages/django/core/handlers/exception.py", line 55, in inner
    response = get_response(request)
               ^^^^^^^^^^^^^^^^^^^^^
  File "/home/ubuntu/Stackly_AI/venv/lib/python3.12/site-packages/django/utils/deprecation.py", line 120, in __call__
    response = response or self.get_response(request)
                           ^^^^^^^^^^^^^^^^^^^^^^^^^^
  File "/home/ubuntu/Stackly_AI/venv/lib/python3.12/site-packages/django/core/handlers/exception.py", line 57, in inner
    response = response_for_exception(request, exc)
               ^^^^^^^^^^^^^^^^^^^^^^^^^^^^^^^^^^^^
  File "/home/ubuntu/Stackly_AI/venv/lib/python3.12/site-packages/django/core/handlers/exception.py", line 141, in response_for_exception
    response = handle_uncaught_exception(
               ^^^^^^^^^^^^^^^^^^^^^^^^^^
  File "/home/ubuntu/Stackly_AI/venv/lib/python3.12/site-packages/django/core/handlers/exception.py", line 182, in handle_uncaught_exception
    return debug.technical_500_response(request, *exc_info)
           ^^^^^^^^^^^^^^^^^^^^^^^^^^^^^^^^^^^^^^^^^^^^^^^^
  File "/home/ubuntu/Stackly_AI/venv/lib/python3.12/site-packages/django/views/debug.py", line 69, in technical_500_response
    html = reporter.get_traceback_html()
           ^^^^^^^^^^^^^^^^^^^^^^^^^^^^^
  File "/home/ubuntu/Stackly_AI/venv/lib/python3.12/site-packages/django/views/debug.py", line 428, in get_traceback_html
    c = Context(self.get_traceback_data(), use_l10n=False)
                ^^^^^^^^^^^^^^^^^^^^^^^^^
  File "/home/ubuntu/Stackly_AI/venv/lib/python3.12/site-packages/django/views/debug.py", line 397, in get_traceback_data
    "settings": self.filter.get_safe_settings(),
                ^^^^^^^^^^^^^^^^^^^^^^^^^^^^^^^
  File "/home/ubuntu/Stackly_AI/venv/lib/python3.12/site-packages/django/views/debug.py", line 156, in get_safe_settings
    settings_dict[k] = self.cleanse_setting(k, getattr(settings, k))
                                               ^^^^^^^^^^^^^^^^^^^^
  File "/home/ubuntu/Stackly_AI/venv/lib/python3.12/site-packages/django/conf/__init__.py", line 90, in __getattr__
    raise ImproperlyConfigured("The SECRET_KEY setting must not be empty.")
django.core.exceptions.ImproperlyConfigured: The SECRET_KEY setting must not be empty.

During handling of the above exception, another exception occurred:

Traceback (most recent call last):
  File "/home/ubuntu/Stackly_AI/venv/lib/python3.12/site-packages/django/core/handlers/exception.py", line 55, in inner
    response = get_response(request)
               ^^^^^^^^^^^^^^^^^^^^^
  File "/home/ubuntu/Stackly_AI/venv/lib/python3.12/site-packages/django/utils/deprecation.py", line 120, in __call__
    response = response or self.get_response(request)
                           ^^^^^^^^^^^^^^^^^^^^^^^^^^
  File "/home/ubuntu/Stackly_AI/venv/lib/python3.12/site-packages/django/core/handlers/exception.py", line 57, in inner
    response = response_for_exception(request, exc)
               ^^^^^^^^^^^^^^^^^^^^^^^^^^^^^^^^^^^^
  File "/home/ubuntu/Stackly_AI/venv/lib/python3.12/site-packages/django/core/handlers/exception.py", line 141, in response_for_exception
    response = handle_uncaught_exception(
               ^^^^^^^^^^^^^^^^^^^^^^^^^^
  File "/home/ubuntu/Stackly_AI/venv/lib/python3.12/site-packages/django/core/handlers/exception.py", line 182, in handle_uncaught_exception
    return debug.technical_500_response(request, *exc_info)
           ^^^^^^^^^^^^^^^^^^^^^^^^^^^^^^^^^^^^^^^^^^^^^^^^
  File "/home/ubuntu/Stackly_AI/venv/lib/python3.12/site-packages/django/views/debug.py", line 69, in technical_500_response
    html = reporter.get_traceback_html()
           ^^^^^^^^^^^^^^^^^^^^^^^^^^^^^
  File "/home/ubuntu/Stackly_AI/venv/lib/python3.12/site-packages/django/views/debug.py", line 428, in get_traceback_html
    c = Context(self.get_traceback_data(), use_l10n=False)
                ^^^^^^^^^^^^^^^^^^^^^^^^^
  File "/home/ubuntu/Stackly_AI/venv/lib/python3.12/site-packages/django/views/debug.py", line 397, in get_traceback_data
    "settings": self.filter.get_safe_settings(),
                ^^^^^^^^^^^^^^^^^^^^^^^^^^^^^^^
  File "/home/ubuntu/Stackly_AI/venv/lib/python3.12/site-packages/django/views/debug.py", line 156, in get_safe_settings
    settings_dict[k] = self.cleanse_setting(k, getattr(settings, k))
                                               ^^^^^^^^^^^^^^^^^^^^
  File "/home/ubuntu/Stackly_AI/venv/lib/python3.12/site-packages/django/conf/__init__.py", line 90, in __getattr__
    raise ImproperlyConfigured("The SECRET_KEY setting must not be empty.")
django.core.exceptions.ImproperlyConfigured: The SECRET_KEY setting must not be empty.

During handling of the above exception, another exception occurred:

Traceback (most recent call last):
  File "/home/ubuntu/Stackly_AI/venv/lib/python3.12/site-packages/django/core/handlers/exception.py", line 55, in inner
    response = get_response(request)
               ^^^^^^^^^^^^^^^^^^^^^
  File "/home/ubuntu/Stackly_AI/venv/lib/python3.12/site-packages/django/utils/deprecation.py", line 120, in __call__
    response = response or self.get_response(request)
                           ^^^^^^^^^^^^^^^^^^^^^^^^^^
  File "/home/ubuntu/Stackly_AI/venv/lib/python3.12/site-packages/django/core/handlers/exception.py", line 57, in inner
    response = response_for_exception(request, exc)
               ^^^^^^^^^^^^^^^^^^^^^^^^^^^^^^^^^^^^
  File "/home/ubuntu/Stackly_AI/venv/lib/python3.12/site-packages/django/core/handlers/exception.py", line 141, in response_for_exception
    response = handle_uncaught_exception(
               ^^^^^^^^^^^^^^^^^^^^^^^^^^
  File "/home/ubuntu/Stackly_AI/venv/lib/python3.12/site-packages/django/core/handlers/exception.py", line 182, in handle_uncaught_exception
    return debug.technical_500_response(request, *exc_info)
           ^^^^^^^^^^^^^^^^^^^^^^^^^^^^^^^^^^^^^^^^^^^^^^^^
  File "/home/ubuntu/Stackly_AI/venv/lib/python3.12/site-packages/django/views/debug.py", line 69, in technical_500_response
    html = reporter.get_traceback_html()
           ^^^^^^^^^^^^^^^^^^^^^^^^^^^^^
  File "/home/ubuntu/Stackly_AI/venv/lib/python3.12/site-packages/django/views/debug.py", line 428, in get_traceback_html
    c = Context(self.get_traceback_data(), use_l10n=False)
                ^^^^^^^^^^^^^^^^^^^^^^^^^
  File "/home/ubuntu/Stackly_AI/venv/lib/python3.12/site-packages/django/views/debug.py", line 397, in get_traceback_data
    "settings": self.filter.get_safe_settings(),
                ^^^^^^^^^^^^^^^^^^^^^^^^^^^^^^^
  File "/home/ubuntu/Stackly_AI/venv/lib/python3.12/site-packages/django/views/debug.py", line 156, in get_safe_settings
    settings_dict[k] = self.cleanse_setting(k, getattr(settings, k))
                                               ^^^^^^^^^^^^^^^^^^^^
  File "/home/ubuntu/Stackly_AI/venv/lib/python3.12/site-packages/django/conf/__init__.py", line 90, in __getattr__
    raise ImproperlyConfigured("The SECRET_KEY setting must not be empty.")
django.core.exceptions.ImproperlyConfigured: The SECRET_KEY setting must not be empty.

During handling of the above exception, another exception occurred:

Traceback (most recent call last):
  File "/home/ubuntu/Stackly_AI/venv/lib/python3.12/site-packages/django/core/handlers/exception.py", line 55, in inner
    response = get_response(request)
               ^^^^^^^^^^^^^^^^^^^^^
  File "/home/ubuntu/Stackly_AI/venv/lib/python3.12/site-packages/django/utils/deprecation.py", line 120, in __call__
    response = response or self.get_response(request)
                           ^^^^^^^^^^^^^^^^^^^^^^^^^^
  File "/home/ubuntu/Stackly_AI/venv/lib/python3.12/site-packages/django/core/handlers/exception.py", line 57, in inner
    response = response_for_exception(request, exc)
               ^^^^^^^^^^^^^^^^^^^^^^^^^^^^^^^^^^^^
  File "/home/ubuntu/Stackly_AI/venv/lib/python3.12/site-packages/django/core/handlers/exception.py", line 141, in response_for_exception
    response = handle_uncaught_exception(
               ^^^^^^^^^^^^^^^^^^^^^^^^^^
  File "/home/ubuntu/Stackly_AI/venv/lib/python3.12/site-packages/django/core/handlers/exception.py", line 182, in handle_uncaught_exception
    return debug.technical_500_response(request, *exc_info)
           ^^^^^^^^^^^^^^^^^^^^^^^^^^^^^^^^^^^^^^^^^^^^^^^^
  File "/home/ubuntu/Stackly_AI/venv/lib/python3.12/site-packages/django/views/debug.py", line 69, in technical_500_response
    html = reporter.get_traceback_html()
           ^^^^^^^^^^^^^^^^^^^^^^^^^^^^^
  File "/home/ubuntu/Stackly_AI/venv/lib/python3.12/site-packages/django/views/debug.py", line 428, in get_traceback_html
    c = Context(self.get_traceback_data(), use_l10n=False)
                ^^^^^^^^^^^^^^^^^^^^^^^^^
  File "/home/ubuntu/Stackly_AI/venv/lib/python3.12/site-packages/django/views/debug.py", line 397, in get_traceback_data
    "settings": self.filter.get_safe_settings(),
                ^^^^^^^^^^^^^^^^^^^^^^^^^^^^^^^
  File "/home/ubuntu/Stackly_AI/venv/lib/python3.12/site-packages/django/views/debug.py", line 156, in get_safe_settings
    settings_dict[k] = self.cleanse_setting(k, getattr(settings, k))
                                               ^^^^^^^^^^^^^^^^^^^^
  File "/home/ubuntu/Stackly_AI/venv/lib/python3.12/site-packages/django/conf/__init__.py", line 90, in __getattr__
    raise ImproperlyConfigured("The SECRET_KEY setting must not be empty.")
django.core.exceptions.ImproperlyConfigured: The SECRET_KEY setting must not be empty.

During handling of the above exception, another exception occurred:

Traceback (most recent call last):
  File "/home/ubuntu/Stackly_AI/venv/lib/python3.12/site-packages/gunicorn/workers/sync.py", line 135, in handle
    self.handle_request(listener, req, client, addr)
  File "/home/ubuntu/Stackly_AI/venv/lib/python3.12/site-packages/gunicorn/workers/sync.py", line 178, in handle_request
    respiter = self.wsgi(environ, resp.start_response)
               ^^^^^^^^^^^^^^^^^^^^^^^^^^^^^^^^^^^^^^^
  File "/home/ubuntu/Stackly_AI/venv/lib/python3.12/site-packages/django/core/handlers/wsgi.py", line 124, in __call__
    response = self.get_response(request)
               ^^^^^^^^^^^^^^^^^^^^^^^^^^
  File "/home/ubuntu/Stackly_AI/venv/lib/python3.12/site-packages/django/core/handlers/base.py", line 140, in get_response
    response = self._middleware_chain(request)
               ^^^^^^^^^^^^^^^^^^^^^^^^^^^^^^^
  File "/home/ubuntu/Stackly_AI/venv/lib/python3.12/site-packages/django/core/handlers/exception.py", line 57, in inner
    response = response_for_exception(request, exc)
               ^^^^^^^^^^^^^^^^^^^^^^^^^^^^^^^^^^^^
  File "/home/ubuntu/Stackly_AI/venv/lib/python3.12/site-packages/django/core/handlers/exception.py", line 141, in response_for_exception
    response = handle_uncaught_exception(
               ^^^^^^^^^^^^^^^^^^^^^^^^^^
  File "/home/ubuntu/Stackly_AI/venv/lib/python3.12/site-packages/django/core/handlers/exception.py", line 182, in handle_uncaught_exception
    return debug.technical_500_response(request, *exc_info)
           ^^^^^^^^^^^^^^^^^^^^^^^^^^^^^^^^^^^^^^^^^^^^^^^^
  File "/home/ubuntu/Stackly_AI/venv/lib/python3.12/site-packages/django/views/debug.py", line 69, in technical_500_response
    html = reporter.get_traceback_html()
           ^^^^^^^^^^^^^^^^^^^^^^^^^^^^^
  File "/home/ubuntu/Stackly_AI/venv/lib/python3.12/site-packages/django/views/debug.py", line 428, in get_traceback_html
    c = Context(self.get_traceback_data(), use_l10n=False)
                ^^^^^^^^^^^^^^^^^^^^^^^^^
  File "/home/ubuntu/Stackly_AI/venv/lib/python3.12/site-packages/django/views/debug.py", line 397, in get_traceback_data
    "settings": self.filter.get_safe_settings(),
                ^^^^^^^^^^^^^^^^^^^^^^^^^^^^^^^
  File "/home/ubuntu/Stackly_AI/venv/lib/python3.12/site-packages/django/views/debug.py", line 156, in get_safe_settings
    settings_dict[k] = self.cleanse_setting(k, getattr(settings, k))
                                               ^^^^^^^^^^^^^^^^^^^^
  File "/home/ubuntu/Stackly_AI/venv/lib/python3.12/site-packages/django/conf/__init__.py", line 90, in __getattr__
    raise ImproperlyConfigured("The SECRET_KEY setting must not be empty.")
django.core.exceptions.ImproperlyConfigured: The SECRET_KEY setting must not be empty.
[2025-10-13 14:18:15 +0000] [9847] [INFO] Worker exiting (pid: 9847)
[2025-10-13 14:18:15 +0000] [9846] [INFO] Handling signal: term
[2025-10-13 14:18:15 +0000] [9848] [INFO] Worker exiting (pid: 9848)
[2025-10-13 14:18:15 +0000] [9849] [INFO] Worker exiting (pid: 9849)
[2025-10-13 14:18:15 +0000] [9846] [ERROR] Worker (pid:9847) was sent SIGTERM!
[2025-10-13 14:18:15 +0000] [9846] [INFO] Shutting down: Master
